Workbook

Sheet URL
A1: No | B1: URL
A2: 1 | B2: https://demo-cbs.finasit.jits.digital/login/
A3: 2 | B3: https://test-cbs.shwesit.jits.digital/login/
A4: 3 | B4: https://27.3.1.198:5017/login/

Sheet ListUser
A1: No | B1: Username | C1: Password | D1: RowStart | E1: RowIndex
A2: 1 | B2: cashier001 | C2: Sh@123456 | D2: 1 | E2: 20
A3: 2 | B3: cashier001 | C3: Sh@123456 | D3: 21 | E3: 20
A4: 3 | B4: cashier001 | C4: Sh@123456 | D4: 41 | E4: 20
A5: 4 | B5: cashier001 | C5: Sh@123456 | D5: 61 | E5: 20
A6: 5 | B6: cashier002 | C6: Sh@123456 | D6: 81 | E6: 20
A7: 6 | B7: cashier002 | C7: Sh@123456 | D7: 101 | E7: 20
A8: 7 | B8: cashier002 | C8: Sh@123456 | D8: 121 | E8: 20
A9: 8 | B9: cashier002 | C9: Sh@123456 | D9: 141 | E9: 20
A10: 9 | B10: cashier003 | C10: Sh@123456 | D10: 161 | E10: 20
A11: 10 | B11: cashier003 | C11: Sh@123456 | D11: 181 | E11: 3
A12: 11 | B12: cashier003 | C12: Sh@123456 | D12: 201 | E12: 20
A13: 12 | B13: cashier003 | C13: Sh@123456 | D13: 221 | E13: 20
... A45: 44 | B45: cashier999 | C45: Sh@123456 | D45: 861 | E45: 20

Sheet ListDataTest
A1: No | B1: Note | C1: CustomerCode | D1: CustomerType | E1: CatalogueCode | F1: RelationshipManager | G1: DepositAccount | H1: AmountDeposit | I1: AmountDepositMask | J1: WithdrawAmount | K1: WithdrawAmountMask | L1: FromSerial | M1: FromSerialMask | N1: ToSerial | O1: ToSerialMask | P1: NumberOfLeaves | Q1: NumberOfBook
A2: 1 | C2: 1-1-001572 | D2: Single customer | E2: CAMMK0000 | F2: 01009 - Thandar Kyaw | G2: 11-002-993110-5 | H2: 5000000.49 | I2: 5,000,000.49 | J2: 5000000.49 | K2: 5,000,000.49 | L2: AT000001 | M2: AT-000001 | N2: AT000100 | O2: AT-000100 | P2: 25 | Q2: 4
A3: 2

Sheet ListTransFO
A1: No | B1: TransCode | C1: TransName | D1: RuleName | E1: Parameter | F1: DataInput | G1: Expected | H1: Note
A2: 1 | B2: ACT_DPT | C2: FX accounting - deposit | D2: CheckNotAllowedDepositType | E2: {"AccountNumber":"account_number","NotAllowType":["T"]}
A3: 2 | B3: ACT_DPT | C3: FX accounting - deposit | D3: CatalogAllowTransaction | E3: {"DebitOrCredit":"C","AccountNumber":"account_number","TransactionType":"ACT"}
A4: 3 | B4: ACT_DPT | C4: FX accounting - deposit | D4: CheckAllowedDepositStatus | E4: {"AccountNumber":"account_number","AllowStatus":["N"]}
A5: 4 | B5: CRD_FCD | C5: 5572: Fee collection by deposit | D5: CheckAllowedDepositCurrecy | E5: {"AccountNumber":"account_number","CurrencyCode":"currency_code","AllowStatus":["N","A"],"IsReverse":"is_reverse"}
A6: 5 | B6: CRD_FCD | C6: 5572: Fee collection by deposit | D6: CheckNotAllowedDepositType | E6: {"AccountNumber":"account_number","NotAllowType":["T"]}
A7: 6 | B7: CRD_FCD | C7: 5572: Fee collection by deposit | D7: CheckAllowedDepositStatus | E7: {"AccountNumber":"account_number","AllowStatus":["N"]}
A8: 7 | B8: CRD_IPCT | C8: 5513: Principal and interest collection by transfer | D8: CheckAllowedDepositCurrecy | E8: {"AccountNumber":"account_number","CurrencyCode":"currency_code","AllowStatus":["N","W","D"],"IsReverse":"is_reverse"}
A9: 8 | B9: CRD_IPCT | C9: 5513: Principal and interest collection by transfer | D9: CheckNotAllowedDepositType | E9: {"AccountNumber":"account_number","NotAllowType":["T"]}
A10: 9 | B10: CRD_IPCT | C10: 5513: Principal and interest collection by transfer | D10: CheckAllowedDepositStatus | E10: {"AccountNumber":"account_number","AllowStatus":["N"]}
A11: 10 | B11: CRD_RFD | C11: 55721: Ree refund by transfer | D11: CheckAllowedDepositCurrecy | E11: {"AccountNumber":"account_number","CurrencyCode":"currency_code","AllowStatus":["N","A","D"],"IsReverse":"is_reverse"}
A12: 11 | B12: CRD_RFD | C12: 55721: Ree refund by transfer | D12: CheckNotAllowedDepositType | E12: {"AccountNumber":"account_number","NotAllowType":["T"]}
A13: 12 | B13: CRD_RFD | C13: 55721: Ree refund by transfer | D13: CheckAllowedDepositStatus | E13: {"AccountNumber":"account_number","AllowStatus":["N"]}
... A59: 58 | B59: DPT_CLS | C59: 1193: Close deposit account | D59: CheckEarlyWithdraw | E59: {"AccountNumber":"account_number","ValueDate":"value_date","ListDepositSubtype":["T6"]}
A60: 59 | B60: DPT_CLS, DPT_DLS, DPT_MLS | C60: #N/A | D60: CheckAllowBranch | E60: {"AccountNumber":"account_number", "UserBranch":"current_branch_code"}
A61: 60 | B61: DPT_COD | C61: 1195: Close OD Facility by Cash | D61: CheckNotAllowedDepositStatus | E61: {"AccountNumber":"account_number","NotAllowStatus":["B"]}
A62: 61 | B62: DPT_COG | C62: 1196: Close OD Facility by GL | D62: CheckNotAllowedDepositStatus | E62: {"AccountNumber":"account_number","NotAllowStatus":["B"]}
A63: 62 | B63: DPT_CSH | C63: FX deposit - cash | D63: CheckNotAllowedDepositType | E63: {"AccountNumber":"account_number","NotAllowType":["T"]}
A64: 63 | B64: DPT_CSH | C64: FX deposit - cash | D64: CheckAllowedDepositStatus | E64: {"AccountNumber":"account_number","AllowStatus":["N"]}
A65: 64 | B65: DPT_CTS | C65: 11837: Change status of stock | D65: CheckNotAllowedDepositStatus | E65: {"AccountNumber":"account_number","NotAllowStatus":["R","B"]}
A66: 65 | B66: DPT_CWC | C66: 1121: Cash withdrawal by cheque | D66: HandleDormant | E66: {"AccountNumber":"account_number","DebitOrCredit":"D","TransactionType":"CSH","SourceId":"COR","DebitWith":["CSH","DPT","ACT"],"CreditWith":["CSH"],"IgnoreApprove":["MID","DIG"],"UserApprove":"user_approve"}
A67: 66 | B67: DPT_CWC | C67: 1121: Cash withdrawal by cheque | D67: CatalogAllowTransaction | E67: {"DebitOrCredit":"D","AccountNumber":"account_number","TransactionType":"CSH","ErrorCode":"Deposit.NotAllowedDebit"}
A68: 67 | B68: DPT_CWC | C68: 1121: Cash withdrawal by cheque | D68: CheckNotAllowedDepositStatus | E68: {"AccountNumber":"account_number","NotAllowStatus":["C","S","O","B","R"]}
A69: 68 | B69: DPT_CWC | C69: 1121: Cash withdrawal by cheque | D69: CheckNotAllowedDepositStatus | E69: {"AccountNumber":"account_linkage","NotAllowStatus":["C","S","B","R"]}
A70: 69 | B70: DPT_CWM | C70: 1125: Misellaneous debit by cheque | D70: CatalogAllowTransaction | E70: {"DebitOrCredit":"D","AccountNumber":"account_number","TransactionType":"ACT","ErrorCode":"Deposit.NotAllowedDebit"}
A71: 70 | B71: DPT_CWM | C71: 1125: Misellaneous debit by cheque | D71: HandleDormant | E71: {"AccountNumber":"account_number","DebitOrCredit":"D","TransactionType":"ACT","SourceId":"COR","DebitWith":["CSH","DPT","ACT"],"CreditWith":["CSH"],"IgnoreApprove":["MID","DIG"],"UserApprove":"user_approve"}
A72: 71 | B72: DPT_CWM | C72: 1125: Misellaneous debit by cheque | D72: CheckDepositType | E72: {"AccountNumber":"account_number","AllowType":["C"]}
... A200: 199 | B200: TRD_BPM | C200: IBP - Payment | D200: __CheckDepositStatus | E200: {"DepositAccount":"$.request.request_body.data.AccountNumber","AllowStatus":"$.request.request_body.data.AllowStatus"}

Sheet ListTransBO
A1: No | B1: TransCode | C1: TransName | D1: RuleName | E1: Parameter | F1: DataInput | G1: Expected | H1: Note
A2: 1 | B2: DPT_INSERT_CATALOG | C2: Insert deposit catalog | D2: CheckAllowRollover | E2: {"Rollover":"rollover","AllowRollover":"N|P", "Condition": "{\"expression\":{\"func\":\"IsStringEqual\",\"type\":\"boolean\",\"paras\":[\"deposit_sub_type\",\"T6\"]}}"}
A3: 2 | B3: DPT_UPDATE_ACCOUNTLINKAGE | C3: Update account linkage | D3: ValidateAccountlinkage | E3: {"IsCreate":false,"MasterAccountNumber":"master_account_number","ListAccountLinkage":"list_account_linkage","OneToOne":{"LinkageClass":"A|I|F","AllowDepositType":"C|S"},"ManyToOne":{"LinkageClass":"A|I|F","AllowDepositType":"C|S"},"Condition":"{\"expression\":{\"func\":\"IsStringEqual\",\"type\":\"boolean\",\"paras\":[\"deposit_type\",\"C\"]}}"}
A4: 3 | B4: DPT_UPDATE_ACCOUNTLINKAGE | C4: Update account linkage | D4: ValidateAccountlinkage | E4: {"IsCreate":false,"MasterAccountNumber":"master_account_number","ListAccountLinkage":"list_account_linkage","OneToOne":{"LinkageClass":"A|I|F","AllowDepositType":"C|S"},"ManyToOne":{"LinkageClass":"A|I|F","AllowDepositType":"C|S"},"Condition":"{\"expression\":{\"func\":\"IsStringEqual\",\"type\":\"boolean\",\"paras\":[\"deposit_type\",\"S\"]}}"}
A5: 4 | B5: DPT_UPDATE_ACCOUNTLINKAGE | C5: Update account linkage | D5: ValidateAccountlinkage | E5: {"IsCreate":false,"MasterAccountNumber":"master_account_number","ListAccountLinkage":"list_account_linkage","OneToOne":{"LinkageClass":"A|I","AllowDepositType":"C|S"},"ManyToOne":{"LinkageClass":"A|I","AllowDepositType":"C|S"},"Condition":"{\"expression\":{\"func\":\"IsStringEqual\",\"type\":\"boolean\",\"paras\":[\"deposit_type\",\"T\"]}}"}
A6: 5 | B6: DPT_UPDATE_CATALOG | C6: Update deposit catalog | D6: CheckAllowRollover | E6: {"Rollover":"rollover","AllowRollover":"N|P", "Condition": "{\"expression\":{\"func\":\"IsStringEqual\",\"type\":\"boolean\",\"paras\":[\"deposit_sub_type\",\"T6\"]}}"}
A7: 6 | B7: DPT_UPDATE_DEPOSIT | C7: Update deposit account | D7: ValidateSweeping | E7: {"SweepingStatus":"sweeping_status","SweepingType":"sweeping_type","MasterAccount":"account_number","AllowStatusMasterAccount":["N"],"AllowDepositTypeMasterAccount":["C","S"],"SurplusAccount":"surplus_account","DeficitAccount":"deficit_account","AllowDepositTypeSurplusAccount":["C","S"],"AllowStatusSurplusAccount":["N","W"],"AllowDepositTypeDeficitAccount":["C","S"],"AllowStatusDeficitAccount":["N"]}

Sheet Sheet2
C1: Field name | D1: Field type | E1: Required
C2: Branch code | D2: Text | E2: Yes
C3: Old branch ID | D3: Text | E3: No
C4: Branch name | D4: Text | E4: Yes
C5: Branch address | D5: Text | E5: No
C6: Branch type | D6: Dropdown (Physical) | E6: Yes
C7: Branch phone | D7: Text | E7: No
C8: Phone number (Home, Cell, Telex) | D8: Expandable Section | E8: No
C9: Office | D9: Text | E9: No
C10: Facsimile | D10: Text | E10: No
C11: Tax code | D11: Text | E11: No
C12: Base currency code | D12: Dropdown (MMK) | E12: Yes
... C25: Online | D25: Dropdown (Yes) | E25: Yes
D35: =28+7 -> 35

Sheet ListTransAPI
A1: No | B1: TransCode | C1: TransName | D1: RuleName | E1: Parameter | F1: DataInput | G1: Expected | H1: Note
A2: 1 | B2: CSH_DPT_GL_MID | C2: Cash deposit gl middleware | D2: ValidateListDepositAccount | E2: {"ListAccountNumber":"list_deposit_account","ListCurrencyCode":"list_currency_code","AllowType":["C","S"],"AllowStatus":["N","W"],"AllowDifferentCurrency":false}
A3: 2 | B3: DPT_ACT_MID | C3: Transfer Deposit Accounting middleware | D3: ValidateListDepositAccount | E3: {"ListAccountNumber":"list_deposit_account","ListCurrencyCode":"list_currency_code","AllowType":["C","S"],"AllowStatus":["N","W"],"AllowDifferentCurrency":false}
A4: 3 | B4: DPT_BATCH_TRANSFER | C4: Batch transfer | D4: FundTransferValidate | E4: {"CheckCatalog":true,"DebitOrCredit":"posting_side","AccountNumber":"account_number","TransactionType":"transaction_type","NotAllowType":["T"],"AllowStatus":["N"]}
A5: 4 | B5: DPT_BATCH_TRANSFER | C5: Batch transfer | D5: __FundTransferValidate | E5: {"CheckCatalog":true,"TransferData":"$.request.request_body.data.TransferData","NotAllowType":"T","DebitAllowStatus":"N|D","CreditAllowStatus":"N|D|W","IsVerify":"$.request.request_body.data.IsVerify","DebitWith":"CSH|DPT|ACT","CreditWith":"CSH","IgnoreApprove":"B|D|L|M|N|O|P|Q|U|Z"}
A6: 5 | B6: DPT_DPT_SO | C6: FX deposit- deposit standing order | D6: CatalogAllowTransaction | E6: {"DebitOrCredit":"D","AccountNumber":"debit_account_number","TransactionType":"DPT"}
A7: 6 | B7: DPT_DPT_SO | C7: FX deposit- deposit standing order | D7: CheckNotAllowedDepositType | E7: {"AccountNumber":"debit_account_number","NotAllowType":["T"]}
A8: 7 | B8: DPT_DPT_SO | C8: FX deposit- deposit standing order | D8: CheckAllowedDepositStatus | E8: {"AccountNumber":"debit_account_number","AllowStatus":["N"]}
A9: 8 | B9: DPT_DPT_SO | C9: FX deposit- deposit standing order | D9: CatalogAllowTransaction | E9: {"DebitOrCredit":"C","AccountNumber":"credit_account_number","TransactionType":"DPT"}
A10: 9 | B10: DPT_DPT_SO | C10: FX deposit- deposit standing order | D10: CheckNotAllowedDepositType | E10: {"AccountNumber":"credit_account_number","NotAllowType":["T"]}
A11: 10 | B11: DPT_DPT_SO | C11: FX deposit- deposit standing order | D11: CheckAllowedDepositStatus | E11: {"AccountNumber":"credit_account_number","AllowStatus":["N"]}
A12: 11 | B12: DPT_FUND_TRANSFER | C12: Fund transfer | D12: FundTransferValidate | E12: {"CheckCatalog":true,"DebitOrCredit":"posting_side","AccountNumber":"account_number","TransactionType":"transaction_type","NotAllowType":["T"],"AllowStatus":["N"]}
A13: 12 | B13: DPT_FUND_TRANSFER | C13: Fund transfer | D13: __FundTransferValidate | E13: {"CheckCatalog":true,"TransferData":"$.request.request_body.data.TransferData","NotAllowType":"T","DebitAllowStatus":"N|D","CreditAllowStatus":"N|D|W","IsVerify":"$.request.request_body.data.IsVerify","DebitWith":"CSH|DPT|ACT","CreditWith":"CSH","IgnoreApprove":"B|D|L|M|N|O|P|Q|U|Z"}
... A191: 190 | B191: DPT_TRF_MOMONEY | C191: Transfer deposit to deposit Momoney | D191: __CatalogAllowTransaction | E191: {"AccountNumber":"$.request.request_body.data.DebitAccountNumber","DebitOrCredit":"D","TransactionType":"DPT"}

Sheet ListTrans
A1: TransCode | B1: TransName
A2: DPT_UPDATE_DEPOSIT | B2: {"en":"Update deposit account","vi":""} | C2: =MID(B2, FIND("en"":""", B2) + 5, FIND(""",""vi", B2) - (FIND("en"":""", B2) + 5)) -> Update deposit account
A3: ACT_DPT | B3: {"en":"FX accounting - deposit","vi":"FX accounting - cash"} | C3: =MID(B3, FIND("en"":""", B3) + 5, FIND(""",""vi", B3) - (FIND("en"":""", B3) + 5)) -> FX accounting - deposit
A4: CRD_FCD | B4: {"en":"5572: Fee collection by deposit","vi":""} | C4: =MID(B4, FIND("en"":""", B4) + 5, FIND(""",""vi", B4) - (FIND("en"":""", B4) + 5)) -> 5572: Fee collection by deposit
A5: CRD_IPCT | B5: {"en":"5513: Principal and interest collection by transfer","vi":""} | C5: =MID(B5, FIND("en"":""", B5) + 5, FIND(""",""vi", B5) - (FIND("en"":""", B5) + 5)) -> 5513: Principal and interest collection by transfer
A6: CRD_RFD | B6: {"en":"55721: Ree refund by transfer","vi":""} | C6: =MID(B6, FIND("en"":""", B6) + 5, FIND(""",""vi", B6) - (FIND("en"":""", B6) + 5)) -> 55721: Ree refund by transfer
A7: CRD_TDR | B7: {"en":"5523: Disbursement by transfer","vi":""} | C7: =MID(B7, FIND("en"":""", B7) + 5, FIND(""",""vi", B7) - (FIND("en"":""", B7) + 5)) -> 5523: Disbursement by transfer
A8: CSH_DPT | B8: {"en":"FX cash - Deposit","vi":"FX cash - Deposit"} | C8: =MID(B8, FIND("en"":""", B8) + 5, FIND(""",""vi", B8) - (FIND("en"":""", B8) + 5)) -> FX cash - Deposit
A9: DPT_ACT | B9: {"en":"FX deposit - accounting","vi":"FX deposit - accounting"} | C9: =MID(B9, FIND("en"":""", B9) + 5, FIND(""",""vi", B9) - (FIND("en"":""", B9) + 5)) -> FX deposit - accounting
A10: DPT_APR | B10: {"en":"Approve deposit account","vi":""} | C10: =MID(B10, FIND("en"":""", B10) + 5, FIND(""",""vi", B10) - (FIND("en"":""", B10) + 5)) -> Approve deposit account
A11: DPT_BLK | B11: {"en":"11840: Block account","vi":""} | C11: =MID(B11, FIND("en"":""", B11) + 5, FIND(""",""vi", B11) - (FIND("en"":""", B11) + 5)) -> 11840: Block account
A12: DPT_CAS | B12: {"en":"11841: Change account status","vi":""} | C12: =MID(B12, FIND("en"":""", B12) + 5, FIND(""",""vi", B12) - (FIND("en"":""", B12) + 5)) -> 11841: Change account status
A13: DPT_CCI | B13: {"en":"11806: Gift cheque issued","vi":""} | C13: =MID(B13, FIND("en"":""", B13) + 5, FIND(""",""vi", B13) - (FIND("en"":""", B13) + 5)) -> 11806: Gift cheque issued
... A124: DPT_IPR | B124: {"en":"Payment Interest For Prepaid Fixed Deposit","vi":""} | C124: =MID(B124, FIND("en"":""", B124) + 5, FIND(""",""vi", B124) - (FIND("en"":""", B124) + 5)) -> Payment Interest For Prepaid Fixed Deposit

Sheet Sheet4

Sheet RawData
A1: TransType | B1: WorkflowId | C1: TransName | D1: RuleName | E1: Parameter
A2: FO | B2: ACT_DPT | C2: =VLOOKUP(B2,ListTrans!$A$2:$C$124,3,FALSE) -> FX accounting - deposit | D2: CheckNotAllowedDepositType | E2: {"AccountNumber":"account_number","NotAllowType":["T"]}
A3: FO | B3: ACT_DPT | C3: =VLOOKUP(B3,ListTrans!$A$2:$C$124,3,FALSE) -> FX accounting - deposit | D3: CatalogAllowTransaction | E3: {"DebitOrCredit":"C","AccountNumber":"account_number","TransactionType":"ACT"}
A4: FO | B4: ACT_DPT | C4: =VLOOKUP(B4,ListTrans!$A$2:$C$124,3,FALSE) -> FX accounting - deposit | D4: CheckAllowedDepositStatus | E4: {"AccountNumber":"account_number","AllowStatus":["N"]}
A5: FO | B5: CRD_FCD | C5: =VLOOKUP(B5,ListTrans!$A$2:$C$124,3,FALSE) -> 5572: Fee collection by deposit | D5: CheckAllowedDepositCurrecy | E5: {"AccountNumber":"account_number","CurrencyCode":"currency_code","AllowStatus":["N","A"],"IsReverse":"is_reverse"}
A6: FO | B6: CRD_FCD | C6: =VLOOKUP(B6,ListTrans!$A$2:$C$124,3,FALSE) -> 5572: Fee collection by deposit | D6: CheckNotAllowedDepositType | E6: {"AccountNumber":"account_number","NotAllowType":["T"]}
A7: FO | B7: CRD_FCD | C7: =VLOOKUP(B7,ListTrans!$A$2:$C$124,3,FALSE) -> 5572: Fee collection by deposit | D7: CheckAllowedDepositStatus | E7: {"AccountNumber":"account_number","AllowStatus":["N"]}
A8: FO | B8: CRD_IPCT | C8: =VLOOKUP(B8,ListTrans!$A$2:$C$124,3,FALSE) -> 5513: Principal and interest collection by transfer | D8: CheckAllowedDepositCurrecy | E8: {"AccountNumber":"account_number","CurrencyCode":"currency_code","AllowStatus":["N","W","D"],"IsReverse":"is_reverse"}
A9: FO | B9: CRD_IPCT | C9: =VLOOKUP(B9,ListTrans!$A$2:$C$124,3,FALSE) -> 5513: Principal and interest collection by transfer | D9: CheckNotAllowedDepositType | E9: {"AccountNumber":"account_number","NotAllowType":["T"]}
A10: FO | B10: CRD_IPCT | C10: =VLOOKUP(B10,ListTrans!$A$2:$C$124,3,FALSE) -> 5513: Principal and interest collection by transfer | D10: CheckAllowedDepositStatus | E10: {"AccountNumber":"account_number","AllowStatus":["N"]}
A11: FO | B11: CRD_RFD | C11: =VLOOKUP(B11,ListTrans!$A$2:$C$124,3,FALSE) -> 55721: Ree refund by transfer | D11: CheckAllowedDepositCurrecy | E11: {"AccountNumber":"account_number","CurrencyCode":"currency_code","AllowStatus":["N","A","D"],"IsReverse":"is_reverse"}
A12: FO | B12: CRD_RFD | C12: =VLOOKUP(B12,ListTrans!$A$2:$C$124,3,FALSE) -> 55721: Ree refund by transfer | D12: CheckNotAllowedDepositType | E12: {"AccountNumber":"account_number","NotAllowType":["T"]}
A13: FO | B13: CRD_RFD | C13: =VLOOKUP(B13,ListTrans!$A$2:$C$124,3,FALSE) -> 55721: Ree refund by transfer | D13: CheckAllowedDepositStatus | E13: {"AccountNumber":"account_number","AllowStatus":["N"]}
... A173: API | B173: DPT_MDP_POS_VOID_ONUS_CZ | C173: =VLOOKUP(B173,ListTrans!$A$2:$C$124,3,FALSE) -> Miscellaneous deposit VOID1 CardZone | D173: __CardzoneValidate | E173: {"AccountNumber":"$.request.request_body.data.AccountNumber","AllowSubType":"C1|S1|S2|S3|S4|S5|S6|S7|S8","AllowCurrency":"MMK","Amount":"$.request.request_body.data.Amount","AllowStatus":"N|W"}
A174: API | B174: DPT_MDP_POS_VOID_ONUS_CZ | C174: Miscellaneous deposit VOID1 CardZone | D174: __CatalogAllowTransaction | E174: {"DebitOrCredit":"C","AccountNumber":"$.request.request_body.data.AccountNumber","TransactionType":"ACT"}
A175: API | B175: DPT_MDP_VOID1_CARDZONE | C175: Miscellaneous deposit VOID1 CardZone | D175: CardzoneValidate | E175: {"AccountNumber":"account_number","AllowSubType":["C1", "S1", "S2", "S3", "S4", "S5", "S6","S7","S8"], "AllowCurrency":["MMK"], "AllowStatus":["N"]}
A176: API | B176: DPT_MDP_VOID2_CARDZONE | C176: Miscellaneous deposit VOID2 CardZone | D176: CardzoneValidate | E176: {"AccountNumber":"account_number","AllowSubType":["C1", "S1", "S2", "S3", "S4", "S5", "S6","S7","S8"], "AllowCurrency":["MMK"], "AllowStatus":["N"]}
A177: FO | B177: DPT_MIP | C177: 1142: Miscellaneous interest payment | D177: CheckDepositType | E177: {"AccountNumber":"account_number","AllowType":["T"]}
A178: FO | B178: DPT_MIP | C178: 1142: Miscellaneous interest payment | D178: HandleDormant | E178: {"AccountNumber":"account_number","DebitOrCredit":"D","TransactionType":"ACT","SourceId":"COR","DebitWith":["CSH","DPT","ACT"],"CreditWith":["CSH"],"IgnoreApprove":["MID","DIG"],"UserApprove":"user_approve"}
A179: FO | B179: DPT_MIP | C179: 1142: Miscellaneous interest payment | D179: CheckAllowedDepositStatus | E179: {"AccountNumber":"account_number","AllowStatus":["N", "A", "D", "M"]}
A180: FO | B180: DPT_MLS | C180: 1191: Close deposit account by miscellaneous | D180: CatalogAllowTransaction | E180: {"DebitOrCredit":"D","AccountNumber":"account_number","TransactionType":"DPT","ErrorCode":"Deposit.NotAllowedDebit"}
A181: FO | B181: DPT_MLS | C181: 1191: Close deposit account by miscellaneous | D181: HandleDormant | E181: {"AccountNumber":"account_number","DebitOrCredit":"D","TransactionType":"DPT","SourceId":"COR","DebitWith":["CSH","DPT","ACT"],"CreditWith":["CSH"],"IgnoreApprove":["MID","DIG"],"UserApprove":"user_approve"}
A182: FO | B182: DPT_MLS | C182: 1191: Close deposit account by miscellaneous | D182: CheckNotAllowedDepositStatus | E182: {"AccountNumber":"account_number","NotAllowStatus":["C", "S", "B", "E", "D", "R"]}
A183: FO | B183: DPT_MLS | C183: 1191: Close deposit account by miscellaneous | D183: CheckAllowBranch | E183: {"AccountNumber":"account_number", "UserBranch":"current_branch_code"}
A184: FO | B184: DPT_MLS | C184: 1191: Close deposit account by miscellaneous | D184: CheckDepositAccountIsLinked | E184: {"AccountNumber":"account_number"}
A185: FO | B185: DPT_MLS | C185: 1191: Close deposit account by miscellaneous | D185: CheckEarlyWithdraw | E185: {"AccountNumber":"account_number","ValueDate":"value_date","ListDepositSubtype":["T6"]}
... A396: FO | B396: TRD_BPM | C396: IBP - Payment | D396: __CheckDepositStatus | E396: {"DepositAccount":"$.request.request_body.data.AccountNumber","AllowStatus":"$.request.request_body.data.AllowStatus"}

Sheet Sheet1
G1: User | H1: Files | I1: Account | J1: File 1 | K1: File 2 | L1: File 3 | M1: File 4
D2: 40 | E2: users | G2: 1 | H2: 4 | I2: 20 | J2: 1 | K2: =J2+$I$2 -> 21 | L2: =K2+$I$2 -> 41 | M2: =L2+$I$2 -> 61
G3: 2 | H3: 4 | I3: 20 | J3: =M2+I3 -> 81 | K3: =J3+$I$3 -> 101 | L3: =K3+$I$3 -> 121 | M3: =L3+$I$3 -> 141
G4: 3 | H4: 4 | I4: 20 | J4: =M3+I4 -> 161 | K4: =J4+$I$3 -> 181 | L4: =K4+$I$3 -> 201 | M4: =L4+$I$3 -> 221
G5: 4 | H5: 4 | I5: 20 | J5: =M4+I5 -> 241 | K5: =J5+$I$3 -> 261 | L5: =K5+$I$3 -> 281 | M5: =L5+$I$3 -> 301
G6: 5 | H6: 4 | I6: 20 | J6: =M5+I6 -> 321 | K6: =J6+$I$3 -> 341 | L6: =K6+$I$3 -> 361 | M6: =L6+$I$3 -> 381
G7: 6 | H7: 4 | I7: 20 | J7: =M6+I7 -> 401 | K7: =J7+$I$3 -> 421 | L7: =K7+$I$3 -> 441 | M7: =L7+$I$3 -> 461
G8: 7 | H8: 4 | I8: 20 | J8: =M7+I8 -> 481 | K8: =J8+$I$3 -> 501 | L8: =K8+$I$3 -> 521 | M8: =L8+$I$3 -> 541
G9: 8 | H9: 4 | I9: 20 | J9: =M8+I9 -> 561 | K9: =J9+$I$3 -> 581 | L9: =K9+$I$3 -> 601 | M9: =L9+$I$3 -> 621
G10: 9 | H10: 4 | I10: 20 | J10: =M9+I10 -> 641 | K10: =J10+$I$3 -> 661 | L10: =K10+$I$3 -> 681 | M10: =L10+$I$3 -> 701
E11: h | F11: 11 | G11: 10 | H11: 4 | I11: 20 | J11: =M10+I11 -> 721 | K11: =J11+$I$3 -> 741 | L11: =K11+$I$3 -> 761 | M11: =L11+$I$3 -> 781
E12: m | F12: 15 | G12: 11 | H12: 4 | I12: 20 | J12: =M11+I12 -> 801 | K12: =J12+$I$3 -> 821 | L12: =K12+$I$3 -> 841 | M12: =L12+$I$3 -> 861
D13: test_account_information_ | E13: run_ | F13: start cmd /k "python | G13: =".py %1 %2""" -> .py %1 %2"
B14: Index | C14: User | D14: File name for test | E14: File name for run | F14: Run CMD
B15: 1 | C15: cashier001 | D15: =$D$13&C15&"_"&B15 -> test_account_information_cashier001_1 | E15: =$E$13&D15 -> run_test_account_information_cashier001_1 | F15: =$F$13&E15&$G$13 -> start cmd /k "python run_test_account_information_cashier001_1.py %1 %2"
B16: 2 | C16: cashier001 | D16: =$D$13&C16&"_"&B16 -> test_account_information_cashier001_2 | E16: =$E$13&D16 -> run_test_account_information_cashier001_2 | F16: =$F$13&E16&$G$13 -> start cmd /k "python run_test_account_information_cashier001_2.py %1 %2"
B17: 3 | C17: cashier001 | D17: =$D$13&C17&"_"&B17 -> test_account_information_cashier001_3 | E17: =$E$13&D17 -> run_test_account_information_cashier001_3 | F17: =$F$13&E17&$G$13 -> start cmd /k "python run_test_account_information_cashier001_3.py %1 %2"
B18: 4 | C18: cashier001 | D18: =$D$13&C18&"_"&B18 -> test_account_information_cashier001_4 | E18: =$E$13&D18 -> run_test_account_information_cashier001_4 | F18: =$F$13&E18&$G$13 -> start cmd /k "python run_test_account_information_cashier001_4.py %1 %2"
B19: 5 | C19: cashier002 | D19: =$D$13&C19&"_"&B19 -> test_account_information_cashier002_5 | E19: =$E$13&D19 -> run_test_account_information_cashier002_5 | F19: =$F$13&E19&$G$13 -> start cmd /k "python run_test_account_information_cashier002_5.py %1 %2"
B20: 6 | C20: cashier002 | D20: =$D$13&C20&"_"&B20 -> test_account_information_cashier002_6 | E20: =$E$13&D20 -> run_test_account_information_cashier002_6 | F20: =$F$13&E20&$G$13 -> start cmd /k "python run_test_account_information_cashier002_6.py %1 %2"
B21: 7 | C21: cashier002 | D21: =$D$13&C21&"_"&B21 -> test_account_information_cashier002_7 | E21: =$E$13&D21 -> run_test_account_information_cashier002_7 | F21: =$F$13&E21&$G$13 -> start cmd /k "python run_test_account_information_cashier002_7.py %1 %2"
B22: 8 | C22: cashier002 | D22: =$D$13&C22&"_"&B22 -> test_account_information_cashier002_8 | E22: =$E$13&D22 -> run_test_account_information_cashier002_8 | F22: =$F$13&E22&$G$13 -> start cmd /k "python run_test_account_information_cashier002_8.py %1 %2"
B23: 9 | C23: cashier003 | D23: =$D$13&C23&"_"&B23 -> test_account_information_cashier003_9 | E23: =$E$13&D23 -> run_test_account_information_cashier003_9 | F23: =$F$13&E23&$G$13 -> start cmd /k "python run_test_account_information_cashier003_9.py %1 %2"
B24: 10 | C24: cashier003 | D24: =$D$13&C24&"_"&B24 -> test_account_information_cashier003_10 | E24: =$E$13&D24 -> run_test_account_information_cashier003_10 | F24: =$F$13&E24&$G$13 -> start cmd /k "python run_test_account_information_cashier003_10.py %1 %2"
B25: 11 | C25: cashier003 | D25: =$D$13&C25&"_"&B25 -> test_account_information_cashier003_11 | E25: =$E$13&D25 -> run_test_account_information_cashier003_11 | F25: =$F$13&E25&$G$13 -> start cmd /k "python run_test_account_information_cashier003_11.py %1 %2"
B26: 12 | C26: cashier003 | D26: =$D$13&C26&"_"&B26 -> test_account_information_cashier003_12 | E26: =$E$13&D26 -> run_test_account_information_cashier003_12 | F26: =$F$13&E26&$G$13 -> start cmd /k "python run_test_account_information_cashier003_12.py %1 %2"
... B58: 44 | C58: cashier999 | D58: =$D$13&C58&"_"&B58 -> test_account_information_cashier999_44 | E58: =$E$13&D58 -> run_test_account_information_cashier999_44 | F58: =$F$13&E58&$G$13 -> start cmd /k "python run_test_account_information_cashier999_44.py %1 %2"

Sheet Sheet3
D2: field_type | E2: in_tab | F2: in_group | G2: in_multi | H2: collap_name | J2: def | K2: (self, title, value): | L2: return self.write_text(title, value, field_type=" | M2: ", in_tab=" | N2: ", in_group=" | O2: ", in_multi=" | P2: ", collap_name=collap_name) | Q2: ")
A3: - ` | B3: bo_write | C3: `: tag name "input": Viết account number, customer code,… trong màn hình BO có tab | D3: T | E3: Y | F3: N | G3: N | H3: self.write_text_input_in_tab, | J3: =$J$2&B3&$K$2&$L$2&D3&$M$2&E3&$N$2&F3&$O$2&G3&$Q$2 -> def bo_write(self, title, value):return self.write_text(title, value, field_type="T", in_tab="Y", in_group="N", in_multi="N")
A4: - ` | B4: bo_write_single | C4: `: tag name "input": Viết account number, customer code,… trong màn hình BO đơn (không có tab) | D4: T | E4: N | F4: N | G4: N | H4: self.write_text_input_non_tab, | J4: =$J$2&B4&$K$2&$L$2&D4&$M$2&E4&$N$2&F4&$O$2&G4&$Q$2 -> def bo_write_single(self, title, value):return self.write_text(title, value, field_type="T", in_tab="N", in_group="N", in_multi="N")
A5: - ` | B5: bo_write_group | C5: `: tag name "input": Viết account number, customer code,… loại field được gom nhóm trong cùng 1 dòng trong màn hình BO có tab | D5: T | E5: Y | F5: Y | G5: N | H5: self.write_text_input_in_tab_group, | J5: =$J$2&B5&$K$2&$L$2&D5&$M$2&E5&$N$2&F5&$O$2&G5&$Q$2 -> def bo_write_group(self, title, value):return self.write_text(title, value, field_type="T", in_tab="Y", in_group="Y", in_multi="N")
A6: - ` | B6: bo_write_group_single | C6: `: tag name "input": Viết account number, customer code,… loại field được gom nhóm trong cùng 1 dòng trong màn hình BO đơn (không có tab) | D6: T | E6: N | F6: Y | G6: N | H6: self.write_text_input_non_tab_group, | J6: =$J$2&B6&$K$2&$L$2&D6&$M$2&E6&$N$2&F6&$O$2&G6&$Q$2 -> def bo_write_group_single(self, title, value):return self.write_text(title, value, field_type="T", in_tab="N", in_group="Y", in_multi="N")
A7: - ` | B7: bo_write_text | C7: `: tag name "textarea": Viết account name, customer name,… trong màn hình BO có tab | D7: A | E7: Y | F7: N | G7: N | H7: self.write_text_textarea_in_tab, | J7: =$J$2&B7&$K$2&$L$2&D7&$M$2&E7&$N$2&F7&$O$2&G7&$Q$2 -> def bo_write_text(self, title, value):return self.write_text(title, value, field_type="A", in_tab="Y", in_group="N", in_multi="N")
A8: - ` | B8: bo_write_text_single | C8: `: tag name "textarea": Viết account name, customer name,… trong màn hình BO đơn (không có tab) | D8: A | E8: N | F8: N | G8: N | H8: self.write_text_textarea_non_tab, | J8: =$J$2&B8&$K$2&$L$2&D8&$M$2&E8&$N$2&F8&$O$2&G8&$Q$2 -> def bo_write_text_single(self, title, value):return self.write_text(title, value, field_type="A", in_tab="N", in_group="N", in_multi="N")
A9: - ` | B9: bo_write_text_group | C9: `: tag name "textarea": Viết account name, customer name,… loại field được gom nhóm trong cùng 1 dòng trong màn hình BO có tab | D9: A | E9: Y | F9: Y | G9: N | H9: self.write_text_textarea_in_tab_group, | J9: =$J$2&B9&$K$2&$L$2&D9&$M$2&E9&$N$2&F9&$O$2&G9&$Q$2 -> def bo_write_text_group(self, title, value):return self.write_text(title, value, field_type="A", in_tab="Y", in_group="Y", in_multi="N")
A10: - ` | B10: bo_write_text_group_single | C10: `: tag name "textarea": Viết account name, customer name,… loại field được gom nhóm trong cùng 1 dòng trong màn hình BO đơn (không có tab) | D10: A | E10: N | F10: Y | G10: N | H10: self.write_text_textarea_non_tab_group, | J10: =$J$2&B10&$K$2&$L$2&D10&$M$2&E10&$N$2&F10&$O$2&G10&$Q$2 -> def bo_write_text_group_single(self, title, value):return self.write_text(title, value, field_type="A", in_tab="N", in_group="Y", in_multi="N")
A11: - ` | B11: bo_write_date | C11: `: Viết date trong màn hình BO có tab | D11: D | E11: Y | F11: N | G11: N | H11: self.write_date_input_in_tab, | J11: =$J$2&B11&$K$2&$L$2&D11&$M$2&E11&$N$2&F11&$O$2&G11&$Q$2 -> def bo_write_date(self, title, value):return self.write_text(title, value, field_type="D", in_tab="Y", in_group="N", in_multi="N")
A12: - ` | B12: bo_write_date_single | C12: `: Viết date trong màn hình BO đơn (không có tab) | D12: D | E12: N | F12: N | G12: N | H12: self.write_date_input_non_tab, | J12: =$J$2&B12&$K$2&$L$2&D12&$M$2&E12&$N$2&F12&$O$2&G12&$Q$2 -> def bo_write_date_single(self, title, value):return self.write_text(title, value, field_type="D", in_tab="N", in_group="N", in_multi="N")
A13: - ` | B13: bo_write_number | C13: `: Viết number trong màn hình BO có tab | D13: N | E13: Y | F13: N | G13: N | H13: self.write_decimal_input_in_tab, | J13: =$J$2&B13&$K$2&$L$2&D13&$M$2&E13&$N$2&F13&$O$2&G13&$Q$2 -> def bo_write_number(self, title, value):return self.write_text(title, value, field_type="N", in_tab="Y", in_group="N", in_multi="N")
A14: - ` | B14: bo_write_number_single | C14: `: Viết number trong màn hình BO đơn (không có tab) | D14: N | E14: N | F14: N | G14: N | H14: self.write_decimal_input_non_tab, | J14: =$J$2&B14&$K$2&$L$2&D14&$M$2&E14&$N$2&F14&$O$2&G14&$Q$2 -> def bo_write_number_single(self, title, value):return self.write_text(title, value, field_type="N", in_tab="N", in_group="N", in_multi="N")
... A16: - ` | B16: bo_select_single | C16: `: Chọn giá trị trong màn hình BO đơn (không có tab) | D16: S | E16: N | F16: N | G16: N | H16: self.select_non_tab, | J16: =$J$2&B16&$K$2&$L$2&D16&$M$2&E16&$N$2&F16&$O$2&G16&$Q$2 -> def bo_select_single(self, title, value):return self.write_text(title, value, field_type="S", in_tab="N", in_group="N", in_multi="N")
A17: - ` | B17: bo_write_multi | C17: `: tag name "input": Viết account number, customer code,… loại field có multi field con trong màn hình BO có tab | D17: T | E17: Y | F17: N | G17: Y | H17: lambda title, value: self.write_text_input_multi_in_tab(collap_name, title, value), | J17: =$J$2&B17&$K$2&$L$2&D17&$M$2&E17&$N$2&F17&$O$2&G17&$P$2 -> def bo_write_multi(self, title, value):return self.write_text(title, value, field_type="T", in_tab="Y", in_group="N", in_multi="Y", collap_name=collap_name)
A18: - ` | B18: bo_write_multi_single | C18: `: tag name "input": Viết account number, customer code,… loại field có multi field con trong màn hình BO đơn (không có tab) | D18: T | E18: N | F18: N | G18: Y | H18: lambda title, value: self.write_text_input_multi_non_tab(collap_name, title, value), | J18: =$J$2&B18&$K$2&$L$2&D18&$M$2&E18&$N$2&F18&$O$2&G18&$P$2 -> def bo_write_multi_single(self, title, value):return self.write_text(title, value, field_type="T", in_tab="N", in_group="N", in_multi="Y", collap_name=collap_name)
A19: - ` | B19: bo_write_text_multi | C19: `: tag name "textarea": Viết account name, customer name,… loại field có multi field con trong màn hình BO có tab | D19: A | E19: Y | F19: N | G19: Y | H19: lambda title, value: self.write_text_textarea_multi_in_tab(collap_name, title, value), | J19: =$J$2&B19&$K$2&$L$2&D19&$M$2&E19&$N$2&F19&$O$2&G19&$P$2 -> def bo_write_text_multi(self, title, value):return self.write_text(title, value, field_type="A", in_tab="Y", in_group="N", in_multi="Y", collap_name=collap_name)
A20: - ` | B20: bo_write_text_multi_single | C20: `: tag name "textarea": Viết account name, customer name,… loại field có multi field con trong màn hình BO đơn (không có tab) | D20: A | E20: N | F20: N | G20: Y | H20: lambda title, value: self.write_text_textarea_multi_non_tab(collap_name, title, value), | J20: =$J$2&B20&$K$2&$L$2&D20&$M$2&E20&$N$2&F20&$O$2&G20&$P$2 -> def bo_write_text_multi_single(self, title, value):return self.write_text(title, value, field_type="A", in_tab="N", in_group="N", in_multi="Y", collap_name=collap_name)
D23: field_type | E23: in_tab | F23: in_group | G23: in_multi | H23: collap_name
A24: - ` | B24: fo_write | C24: `: tag name "input": Viết account number, customer code,… trong màn hình FO | D24: T | E24: N | F24: N | G24: N | H24: self.write_text_input_non_tab, | J24: =$J$2&B24&$K$2&$L$2&D24&$M$2&E24&$N$2&F24&$O$2&G24&$Q$2 -> def fo_write(self, title, value):return self.write_text(title, value, field_type="T", in_tab="N", in_group="N", in_multi="N")
A25: - ` | B25: fo_write_group | C25: `: tag name "input": Viết account number, customer code,… loại field được gom nhóm trong cùng 1 dòng trong màn hình FO | D25: T | E25: N | F25: Y | G25: N | H25: self.write_text_input_non_tab_group, | J25: =$J$2&B25&$K$2&$L$2&D25&$M$2&E25&$N$2&F25&$O$2&G25&$Q$2 -> def fo_write_group(self, title, value):return self.write_text(title, value, field_type="T", in_tab="N", in_group="Y", in_multi="N")
A26: - ` | B26: fo_write_text | C26: `: tag name "textarea": Viết account name, customer name,… trong màn hình FO | D26: A | E26: N | F26: N | G26: N | H26: self.write_text_textarea_non_tab, | J26: =$J$2&B26&$K$2&$L$2&D26&$M$2&E26&$N$2&F26&$O$2&G26&$Q$2 -> def fo_write_text(self, title, value):return self.write_text(title, value, field_type="A", in_tab="N", in_group="N", in_multi="N")
A27: - ` | B27: fo_write_text_group | C27: `: tag name "textarea": Viết account name, customer name,… loại field được gom nhóm trong cùng 1 dòng trong màn hình FO | D27: A | E27: N | F27: Y | G27: N | H27: self.write_text_textarea_non_tab_group, | J27: =$J$2&B27&$K$2&$L$2&D27&$M$2&E27&$N$2&F27&$O$2&G27&$Q$2 -> def fo_write_text_group(self, title, value):return self.write_text(title, value, field_type="A", in_tab="N", in_group="Y", in_multi="N")
A28: - ` | B28: fo_write_date | C28: `: Viết date trong màn hình FO | D28: D | E28: N | F28: N | G28: N | H28: self.write_date_input_non_tab, | J28: =$J$2&B28&$K$2&$L$2&D28&$M$2&E28&$N$2&F28&$O$2&G28&$Q$2 -> def fo_write_date(self, title, value):return self.write_text(title, value, field_type="D", in_tab="N", in_group="N", in_multi="N")
A29: - ` | B29: fo_write_number | C29: `: Viết number trong màn hình FO | D29: N | E29: N | F29: N | G29: N | H29: self.write_decimal_input_non_tab, | J29: =$J$2&B29&$K$2&$L$2&D29&$M$2&E29&$N$2&F29&$O$2&G29&$Q$2 -> def fo_write_number(self, title, value):return self.write_text(title, value, field_type="N", in_tab="N", in_group="N", in_multi="N")
A30: - ` | B30: fo_select | C30: `: Chọn giá trị trong màn hình FO | D30: S | E30: N | F30: N | G30: N | H30: self.select_non_tab, | J30: =$J$2&B30&$K$2&$L$2&D30&$M$2&E30&$N$2&F30&$O$2&G30&$Q$2 -> def fo_select(self, title, value):return self.write_text(title, value, field_type="S", in_tab="N", in_group="N", in_multi="N")
A31: - ` | B31: fo_write_multi | C31: `: tag name "input": Viết account number, customer code,… loại field có multi field con trong màn hình FO | D31: T | E31: N | F31: N | G31: Y | H31: lambda title, value: self.write_text_input_multi_non_tab(collap_name, title, value), | J31: =$J$2&B31&$K$2&$L$2&D31&$M$2&E31&$N$2&F31&$O$2&G31&$P$2 -> def fo_write_multi(self, title, value):return self.write_text(title, value, field_type="T", in_tab="N", in_group="N", in_multi="Y", collap_name=collap_name)
A32: - ` | B32: fo_write_text_multi | C32: `: tag name "textarea": Viết account name, customer name,… loại field có multi field con trong màn hình FO đơn | D32: A | E32: N | F32: N | G32: Y | H32: lambda title, value: self.write_text_textarea_multi_non_tab(collap_name, title, value), | J32: =$J$2&B32&$K$2&$L$2&D32&$M$2&E32&$N$2&F32&$O$2&G32&$P$2 -> def fo_write_text_multi(self, title, value):return self.write_text(title, value, field_type="A", in_tab="N", in_group="N", in_multi="Y", collap_name=collap_name)
D35: field_type | E35: in_tab | F35: in_group | G35: in_multi | H35: title_front_select | J35: def | K35: (self, title): | L35: return self.get_text(title, field_type=" | M35: ", in_tab=" | N35: ", in_group=" | O35: ", in_multi=" | P35: ", collap_name=collap_name) | Q35: ")
A36: - ` | B36: bo_get_value | C36: `: tag name "input": Lấy ra giá trị account number, customer code,… trong màn hình BO có tab | D36: I | E36: Y | F36: N | G36: N | H36: self.get_text_input_in_tab | J36: =$J$35&B36&$K$35&$L$35&D36&$M$35&E36&$N$35&F36&$O$35&G36&$Q$35 -> def bo_get_value(self, title):return self.get_text(title, field_type="I", in_tab="Y", in_group="N", in_multi="N")
A37: - ` | B37: bo_get_value_single | C37: `: tag name "input": Lấy ra giá trị account number, customer code,… trong màn hình BO đơn (không có tab) | D37: I | E37: N | F37: N | G37: N | H37: self.get_text_input_non_tab | J37: =$J$35&B37&$K$35&$L$35&D37&$M$35&E37&$N$35&F37&$O$35&G37&$Q$35 -> def bo_get_value_single(self, title):return self.get_text(title, field_type="I", in_tab="N", in_group="N", in_multi="N")
A38: - ` | B38: bo_get_value_group | C38: `: tag name "input": Lấy ra giá trị account number, customer code,… loại field được gom nhóm trong cùng 1 dòng trong màn hình BO có tab | D38: I | E38: Y | F38: Y | G38: N | H38: self.get_text_input_in_tab_group | J38: =$J$35&B38&$K$35&$L$35&D38&$M$35&E38&$N$35&F38&$O$35&G38&$Q$35 -> def bo_get_value_group(self, title):return self.get_text(title, field_type="I", in_tab="Y", in_group="Y", in_multi="N")
A39: - ` | B39: bo_get_value_group_single | C39: `: tag name "input": Lấy ra giá trị account number, customer code,… loại field được gom nhóm trong cùng 1 dòng trong màn hình BO đơn (không có tab) | D39: I | E39: N | F39: Y | G39: N | H39: self.get_text_input_non_tab_group | J39: =$J$35&B39&$K$35&$L$35&D39&$M$35&E39&$N$35&F39&$O$35&G39&$Q$35 -> def bo_get_value_group_single(self, title):return self.get_text(title, field_type="I", in_tab="N", in_group="Y", in_multi="N")
A40: - ` | B40: bo_get_select | C40: `: Lấy ra giá trị của select-box, trong màn hình BO có tab | D40: S | E40: Y | F40: N | G40: N | H40: self.get_text_select_in_tab | J40: =$J$35&B40&$K$35&$L$35&D40&$M$35&E40&$N$35&F40&$O$35&G40&$Q$35 -> def bo_get_select(self, title):return self.get_text(title, field_type="S", in_tab="Y", in_group="N", in_multi="N")
A41: - ` | B41: bo_get_select_single | C41: `: Lấy ra giá trị của select-box, trong màn hình BO đơn (không có tab) | D41: S | E41: N | F41: N | G41: N | H41: self.get_text_select_non_tab | J41: =$J$35&B41&$K$35&$L$35&D41&$M$35&E41&$N$35&F41&$O$35&G41&$Q$35 -> def bo_get_select_single(self, title):return self.get_text(title, field_type="S", in_tab="N", in_group="N", in_multi="N")
A42: - ` | B42: bo_get_select_group | C42: `: Lấy ra giá trị của select-box, loại field được gom nhóm trong cùng 1 dòng trong màn hình BO có tab | D42: S | E42: Y | F42: Y | G42: N | H42: lambda title: self.get_text_select_in_tab_group(title_front_select | I42: title) | J42: =$J$35&B42&$K$35&$L$35&D42&$M$35&E42&$N$35&F42&$O$35&G42&$Q$35 -> def bo_get_select_group(self, title):return self.get_text(title, field_type="S", in_tab="Y", in_group="Y", in_multi="N")
A43: - ` | B43: bo_get_select_group_single | C43: `: Lấy ra giá trị của select-box, loại field được gom nhóm trong cùng 1 dòng trong màn hình BO đơn (không có tab) | D43: S | E43: N | F43: Y | G43: N | H43: lambda title: self.get_text_select_non_tab_group(title_front_select | I43: title) | J43: =$J$35&B43&$K$35&$L$35&D43&$M$35&E43&$N$35&F43&$O$35&G43&$Q$35 -> def bo_get_select_group_single(self, title):return self.get_text(title, field_type="S", in_tab="N", in_group="Y", in_multi="N")
A44: - ` | B44: bo_get_text | C44: `: tag name "textarea": Lấy ra giá trị account name, customer name,… trong màn hình BO có tab | D44: A | E44: Y | F44: N | G44: N | H44: self.get_text_textarea_in_tab | J44: =$J$35&B44&$K$35&$L$35&D44&$M$35&E44&$N$35&F44&$O$35&G44&$Q$35 -> def bo_get_text(self, title):return self.get_text(title, field_type="A", in_tab="Y", in_group="N", in_multi="N")
A45: - ` | B45: bo_get_text_single | C45: `: tag name "textarea": Lấy ra giá trị account name, customer name,… trong màn hình BO đơn (không có tab) | D45: A | E45: N | F45: N | G45: N | H45: self.get_text_textarea_non_tab | J45: =$J$35&B45&$K$35&$L$35&D45&$M$35&E45&$N$35&F45&$O$35&G45&$Q$35 -> def bo_get_text_single(self, title):return self.get_text(title, field_type="A", in_tab="N", in_group="N", in_multi="N")
A46: - ` | B46: bo_get_text_group | C46: `: tag name "textarea": Lấy ra giá trị account name, customer name,… loại field được gom nhóm trong cùng 1 dòng trong màn hình BO có tab | D46: A | E46: Y | F46: Y | G46: N | H46: self.get_text_textarea_in_tab_group | J46: =$J$35&B46&$K$35&$L$35&D46&$M$35&E46&$N$35&F46&$O$35&G46&$Q$35 -> def bo_get_text_group(self, title):return self.get_text(title, field_type="A", in_tab="Y", in_group="Y", in_multi="N")
...
