Workbook
Name Pass: '[1]Test Case_ILC'!$H$13

Sheet Version
A4: CBS-SHWE_TC_BO_C# Convert Stored Procedure
D6: Version: 1.0
A7: Version history
A8: Version | B8: Maker | C8: Revision Date | D8: Checker | E8: Approval Date | F8: Document Changes
A9: 1 | B9: NhiDY | C9: 45657 | F9: Create document

Sheet Summary
B2: Bàn giao test case
B3: Ngày | C3: 45659
B4: Giờ | C4: 18h00
B5: Tổng số case | C5: ='Scenario Test'!J39 -> 210
B7: Execute test case lần 1 theo ngày
B8: Date Status | C8: 45657 | D8: 45659 | E8: 45660 | F8: 45663 | G8: 45664 | H8: 45665 | I8: 45666
B9: Pass | C9: =COUNTIFS(TestCase!$G:$G,$B$9,TestCase!$J:$J,C8) -> 2 | D9: =COUNTIFS(TestCase!$G:$G,$B$9,TestCase!$J:$J,D8) -> 52 | E9: =COUNTIFS(TestCase!$G:$G,$B$9,TestCase!$J:$J,E8) -> 77 | F9: =COUNTIFS(TestCase!$G:$G,$B$9,TestCase!$J:$J,F8) -> 8 | G9: =COUNTIFS(TestCase!$G:$G,$B$9,TestCase!$J:$J,G8) -> 10 | H9: =COUNTIFS(TestCase!$G:$G,$B$9,TestCase!$J:$J,H8) -> 10 | I9: =COUNTIFS(TestCase!$G:$G,$B$9,TestCase!$J:$J,I8) -> 32
B10: Fail | C10: =COUNTIFS(TestCase!$G:$G,$B$10,TestCase!$J:$J,C8) -> 0 | D10: =COUNTIFS(TestCase!$G:$G,$B$10,TestCase!$J:$J,D8) -> 0 | E10: =COUNTIFS(TestCase!$G:$G,$B$10,TestCase!$J:$J,E8) -> 0 | F10: =COUNTIFS(TestCase!$G:$G,$B$10,TestCase!$J:$J,F8) -> 0 | G10: =COUNTIFS(TestCase!$G:$G,$B$10,TestCase!$J:$J,G8) -> 0 | H10: =COUNTIFS(TestCase!$G:$G,$B$10,TestCase!$J:$J,H8) -> 0 | I10: =COUNTIFS(TestCase!$G:$G,$B$10,TestCase!$J:$J,I8) -> 0
B11: Block | C11: =COUNTIFS(TestCase!$G:$G,$B$11,TestCase!$J:$J,C8) -> 0 | D11: =COUNTIFS(TestCase!$G:$G,$B$11,TestCase!$J:$J,D8) -> 0 | E11: =COUNTIFS(TestCase!$G:$G,$B$11,TestCase!$J:$J,E8) -> 0 | F11: =COUNTIFS(TestCase!$G:$G,$B$11,TestCase!$J:$J,F8) -> 0 | G11: =COUNTIFS(TestCase!$G:$G,$B$11,TestCase!$J:$J,G8) -> 0 | H11: =COUNTIFS(TestCase!$G:$G,$B$11,TestCase!$J:$J,H8) -> 0 | I11: =COUNTIFS(TestCase!$G:$G,$B$11,TestCase!$J:$J,I8) -> 0
B12: Pending | C12: =COUNTIFS(TestCase!$G:$G,$B$12,TestCase!$K:$K,C8) -> 0 | D12: =COUNTIFS(TestCase!$G:$G,$B$12,TestCase!$K:$K,D8) -> 0 | E12: =COUNTIFS(TestCase!$G:$G,$B$12,TestCase!$K:$K,E8) -> 0 | F12: =COUNTIFS(TestCase!$G:$G,$B$12,TestCase!$K:$K,F8) -> 0 | G12: =COUNTIFS(TestCase!$G:$G,$B$12,TestCase!$K:$K,G8) -> 0 | H12: =COUNTIFS(TestCase!$G:$G,$B$12,TestCase!$K:$K,H8) -> 0 | I12: =COUNTIFS(TestCase!$G:$G,$B$12,TestCase!$K:$K,I8) -> 0
B13: Not Completed | C13: =COUNTIFS(TestCase!$G:$G,$B$13,TestCase!$K:$K,C8) -> 0 | D13: =COUNTIFS(TestCase!$G:$G,$B$13,TestCase!$K:$K,D8) -> 0 | E13: =COUNTIFS(TestCase!$G:$G,$B$13,TestCase!$K:$K,E8) -> 0 | F13: =COUNTIFS(TestCase!$G:$G,$B$13,TestCase!$K:$K,F8) -> 0 | G13: =COUNTIFS(TestCase!$G:$G,$B$13,TestCase!$K:$K,G8) -> 0 | H13: =COUNTIFS(TestCase!$G:$G,$B$13,TestCase!$K:$K,H8) -> 0 | I13: =COUNTIFS(TestCase!$G:$G,$B$13,TestCase!$K:$K,I8) -> 0
B14: Actual execution | C14: =SUM(C9:C13) -> 2 | D14: =SUM(D9:D13) -> 52 | E14: =SUM(E9:E13) -> 77 | F14: =SUM(F9:F13) -> 8 | G14: =SUM(G9:G13) -> 10 | H14: =SUM(H9:H13) -> 10 | I14: =SUM(I9:I13) -> 32
B15: Not yet execution | C15: =$C$5-C14 -> 208 | D15: =C15-D14 -> 156 | E15: =D15-E14 -> 79 | F15: =E15-F14 -> 71 | G15: =F15-G14 -> 61 | H15: =G15-H14 -> 51 | I15: =H15-I14 -> 19
B17: Execute test case lần 2 theo ngày
B18: Date Status | C18: 45657 | D18: 45659 | E18: 45660 | F18: 45663 | G18: 45664 | H18: 45665 | I18: 45666
B19: Pass | C19: =COUNTIFS(TestCase!$G:$G,$B$19,TestCase!$K:$K,C18) -> 0 | D19: =COUNTIFS(TestCase!$G:$G,$B$19,TestCase!$K:$K,D18) -> 2 | E19: =COUNTIFS(TestCase!$G:$G,$B$19,TestCase!$K:$K,E18) -> 11 | F19: =COUNTIFS(TestCase!$G:$G,$B$19,TestCase!$K:$K,F18) -> 20 | G19: =COUNTIFS(TestCase!$G:$G,$B$19,TestCase!$K:$K,G18) -> 0 | H19: =COUNTIFS(TestCase!$G:$G,$B$19,TestCase!$K:$K,H18) -> 36 | I19: =COUNTIFS(TestCase!$G:$G,$B$19,TestCase!$K:$K,I18) -> 50
B20: Fail | C20: =COUNTIFS(TestCase!$G:$G,$B$20,TestCase!$K:$K,C18) -> 0 | D20: =COUNTIFS(TestCase!$G:$G,$B$20,TestCase!$K:$K,D18) -> 0 | E20: =COUNTIFS(TestCase!$G:$G,$B$20,TestCase!$K:$K,E18) -> 0 | F20: =COUNTIFS(TestCase!$G:$G,$B$20,TestCase!$K:$K,F18) -> 0 | G20: =COUNTIFS(TestCase!$G:$G,$B$20,TestCase!$K:$K,G18) -> 0 | H20: =COUNTIFS(TestCase!$G:$G,$B$20,TestCase!$K:$K,H18) -> 0 | I20: =COUNTIFS(TestCase!$G:$G,$B$20,TestCase!$K:$K,I18) -> 0
B21: Block | C21: =COUNTIFS(TestCase!$G:$G,$B$21,TestCase!$K:$K,C18) -> 0 | D21: =COUNTIFS(TestCase!$G:$G,$B$21,TestCase!$K:$K,D18) -> 0 | E21: =COUNTIFS(TestCase!$G:$G,$B$21,TestCase!$K:$K,E18) -> 0 | F21: =COUNTIFS(TestCase!$G:$G,$B$21,TestCase!$K:$K,F18) -> 0 | G21: =COUNTIFS(TestCase!$G:$G,$B$21,TestCase!$K:$K,G18) -> 0 | H21: =COUNTIFS(TestCase!$G:$G,$B$21,TestCase!$K:$K,H18) -> 0 | I21: =COUNTIFS(TestCase!$G:$G,$B$21,TestCase!$K:$K,I18) -> 0
B22: Pending | C22: =COUNTIFS(TestCase!$G:$G,$B$22,TestCase!$K:$K,C18) -> 0 | D22: =COUNTIFS(TestCase!$G:$G,$B$22,TestCase!$K:$K,D18) -> 0 | E22: =COUNTIFS(TestCase!$G:$G,$B$22,TestCase!$K:$K,E18) -> 0 | F22: =COUNTIFS(TestCase!$G:$G,$B$22,TestCase!$K:$K,F18) -> 0 | G22: =COUNTIFS(TestCase!$G:$G,$B$22,TestCase!$K:$K,G18) -> 0 | H22: =COUNTIFS(TestCase!$G:$G,$B$22,TestCase!$K:$K,H18) -> 0 | I22: =COUNTIFS(TestCase!$G:$G,$B$22,TestCase!$K:$K,I18) -> 0
B23: Not Completed | C23: =COUNTIFS(TestCase!$G:$G,$B$23,TestCase!$K:$K,C18) -> 0 | D23: =COUNTIFS(TestCase!$G:$G,$B$23,TestCase!$K:$K,D18) -> 0 | E23: =COUNTIFS(TestCase!$G:$G,$B$23,TestCase!$K:$K,E18) -> 0 | F23: =COUNTIFS(TestCase!$G:$G,$B$23,TestCase!$K:$K,F18) -> 0 | G23: =COUNTIFS(TestCase!$G:$G,$B$23,TestCase!$K:$K,G18) -> 0 | H23: =COUNTIFS(TestCase!$G:$G,$B$23,TestCase!$K:$K,H18) -> 0 | I23: =COUNTIFS(TestCase!$G:$G,$B$23,TestCase!$K:$K,I18) -> 0
B24: Actual execution | C24: =SUM(C19:C23) -> 0 | D24: =SUM(D19:D23) -> 2 | E24: =SUM(E19:E23) -> 11 | F24: =SUM(F19:F23) -> 20 | G24: =SUM(G19:G23) -> 0 | H24: =SUM(H19:H23) -> 36 | I24: =SUM(I19:I23) -> 50
B25: Not yet execution | C25: =$C$5-C24 -> 210 | D25: =C25-D24 -> 208 | E25: =D25-E24 -> 197 | F25: =E25-F24 -> 177 | G25: =F25-G24 -> 177 | H25: =G25-H24 -> 141 | I25: =H25-I24 -> 91
B27: Percent execute test case
B28: Percent pass | C28: ='Scenario Test'!K39 -> 0.9714
B29: Percent fail | C29: ='Scenario Test'!L39 -> 0
B30: Percent block | C30: ='Scenario Test'!N39 -> 0
B31: Percent pending | C31: ='Scenario Test'!O39 -> 0
B32: Percent not completed | C32: ='Scenario Test'!P39 -> 0
B33: Percent not run | C33: ='Scenario Test'!M39 -> 0.0286
B35: Execute test case
B36: Pass | C36: ='Scenario Test'!C39 -> 204
B37: Fail | C37: ='Scenario Test'!D39 -> 0
B38: Block | C38: ='Scenario Test'!F39 -> 0
B39: Pending | C39: ='Scenario Test'!G39 -> 0
B40: Not Completed | C40: ='Scenario Test'!H39 -> 0
B41: Not run | C41: ='Scenario Test'!E39 -> 6

Sheet Scenario Test
A3: SUMMARY
A5: Scenario ID | B5: Scenario name | C5: Pass | D5: Fail | E5: + | F5: Block | G5: Pending | H5: Not Completed | I5: - | J5: Total | K5: Percent pass | L5: Percent fail | M5: Percent not run | N5: Percent block | O5: Percent pending | P5: Percent not completed | Q5: Remark
A6: Customer
A7: CTM_001 | B7: SQL_INSERT_CTM: Add customer profile | C7: =COUNTIFS(TestCase!$A:$A,A7,TestCase!$G:$G,$C$5) -> 7 | D7: =COUNTIFS(TestCase!$A:$A,A7,TestCase!$G:$G,$D$5) -> 0 | E7: =COUNTIFS(TestCase!$A:$A,A7,TestCase!$G:$G,$E$5) -> 0 | F7: =COUNTIFS(TestCase!$A:$A,A7,TestCase!$G:$G,$F$5) -> 0 | G7: =COUNTIFS(TestCase!$A:$A,A7,TestCase!$G:$G,$G$5) -> 0 | H7: =COUNTIFS(TestCase!$A:$A,A7,TestCase!$G:$G,$H$5) -> 0 | I7: =COUNTIFS(TestCase!$A:$A,A7,TestCase!$G:$G,$I$5) -> 0 | J7: =SUM(C7:H7) -> 7 | K7: =IFERROR(ROUND(C7/J7,4),0) -> 1 | L7: =IFERROR(ROUND(D7/J7,4),0) -> 0 | M7: =IFERROR(ROUND(E7/J7,4),0) -> 0 | N7: =IFERROR(ROUND(F7/J7,4),0) -> 0 | O7: =IFERROR(ROUND(G7/J7,4),0) -> 0 | P7: =IFERROR(ROUND(H7/J7,4),0) -> 0
A8: CTM_002 | B8: SQL_UPDATE_CTM: Update customer profile | C8: =COUNTIFS(TestCase!$A:$A,A8,TestCase!$G:$G,$C$5) -> 16 | D8: =COUNTIFS(TestCase!$A:$A,A8,TestCase!$G:$G,$D$5) -> 0 | E8: =COUNTIFS(TestCase!$A:$A,A8,TestCase!$G:$G,$E$5) -> 0 | F8: =COUNTIFS(TestCase!$A:$A,A8,TestCase!$G:$G,$F$5) -> 0 | G8: =COUNTIFS(TestCase!$A:$A,A8,TestCase!$G:$G,$G$5) -> 0 | H8: =COUNTIFS(TestCase!$A:$A,A8,TestCase!$G:$G,$H$5) -> 0 | I8: =COUNTIFS(TestCase!$A:$A,A8,TestCase!$G:$G,$I$5) -> 0 | J8: =SUM(C8:H8) -> 16 | K8: =IFERROR(ROUND(C8/J8,4),0) -> 1 | L8: =IFERROR(ROUND(D8/J8,4),0) -> 0 | M8: =IFERROR(ROUND(E8/J8,4),0) -> 0 | N8: =IFERROR(ROUND(F8/J8,4),0) -> 0 | O8: =IFERROR(ROUND(G8/J8,4),0) -> 0 | P8: =IFERROR(ROUND(H8/J8,4),0) -> 0
A9: CTM_003 | B9: SQL_INSERT_MEDIA: Import media file | C9: =COUNTIFS(TestCase!$A:$A,A9,TestCase!$G:$G,$C$5) -> 3 | D9: =COUNTIFS(TestCase!$A:$A,A9,TestCase!$G:$G,$D$5) -> 0 | E9: =COUNTIFS(TestCase!$A:$A,A9,TestCase!$G:$G,$E$5) -> 0 | F9: =COUNTIFS(TestCase!$A:$A,A9,TestCase!$G:$G,$F$5) -> 0 | G9: =COUNTIFS(TestCase!$A:$A,A9,TestCase!$G:$G,$G$5) -> 0 | H9: =COUNTIFS(TestCase!$A:$A,A9,TestCase!$G:$G,$H$5) -> 0 | I9: =COUNTIFS(TestCase!$A:$A,A9,TestCase!$G:$G,$I$5) -> 0 | J9: =SUM(C9:H9) -> 3 | K9: =IFERROR(ROUND(C9/J9,4),0) -> 1 | L9: =IFERROR(ROUND(D9/J9,4),0) -> 0 | M9: =IFERROR(ROUND(E9/J9,4),0) -> 0 | N9: =IFERROR(ROUND(F9/J9,4),0) -> 0 | O9: =IFERROR(ROUND(G9/J9,4),0) -> 0 | P9: =IFERROR(ROUND(H9/J9,4),0) -> 0
A10: CTM_004 | B10: CTM_INSERT_CTM_API: OpenAPI add customer profile | C10: =COUNTIFS(TestCase!$A:$A,A10,TestCase!$G:$G,$C$5) -> 1 | D10: =COUNTIFS(TestCase!$A:$A,A10,TestCase!$G:$G,$D$5) -> 0 | E10: =COUNTIFS(TestCase!$A:$A,A10,TestCase!$G:$G,$E$5) -> 0 | F10: =COUNTIFS(TestCase!$A:$A,A10,TestCase!$G:$G,$F$5) -> 0 | G10: =COUNTIFS(TestCase!$A:$A,A10,TestCase!$G:$G,$G$5) -> 0 | H10: =COUNTIFS(TestCase!$A:$A,A10,TestCase!$G:$G,$H$5) -> 0 | I10: =COUNTIFS(TestCase!$A:$A,A10,TestCase!$G:$G,$I$5) -> 0 | J10: =SUM(C10:H10) -> 1 | K10: =IFERROR(ROUND(C10/J10,4),0) -> 1 | L10: =IFERROR(ROUND(D10/J10,4),0) -> 0 | M10: =IFERROR(ROUND(E10/J10,4),0) -> 0 | N10: =IFERROR(ROUND(F10/J10,4),0) -> 0 | O10: =IFERROR(ROUND(G10/J10,4),0) -> 0 | P10: =IFERROR(ROUND(H10/J10,4),0) -> 0 | Q10: dùng chung step code SQL_INSERT_CTM
A11: Deposit
A12: DPT_001 | B12: DPT_UPDATE_DEPOSIT: Modify deposit account | C12: =COUNTIFS(TestCase!$A:$A,A12,TestCase!$G:$G,$C$5) -> 55 | D12: =COUNTIFS(TestCase!$A:$A,A12,TestCase!$G:$G,$D$5) -> 0 | E12: =COUNTIFS(TestCase!$A:$A,A12,TestCase!$G:$G,$E$5) -> 0 | F12: =COUNTIFS(TestCase!$A:$A,A12,TestCase!$G:$G,$F$5) -> 0 | G12: =COUNTIFS(TestCase!$A:$A,A12,TestCase!$G:$G,$G$5) -> 0 | H12: =COUNTIFS(TestCase!$A:$A,A12,TestCase!$G:$G,$H$5) -> 0 | I12: =COUNTIFS(TestCase!$A:$A,A12,TestCase!$G:$G,$I$5) -> 0 | J12: =SUM(C12:H12) -> 55 | K12: =IFERROR(ROUND(C12/J12,4),0) -> 1 | L12: =IFERROR(ROUND(D12/J12,4),0) -> 0 | M12: =IFERROR(ROUND(E12/J12,4),0) -> 0 | N12: =IFERROR(ROUND(F12/J12,4),0) -> 0 | O12: =IFERROR(ROUND(G12/J12,4),0) -> 0 | P12: =IFERROR(ROUND(H12/J12,4),0) -> 0
A13: DPT_002 | B13: DPT_VIEW_MODIFY_EXT_FIELD: View modify extension fields deposit account | C13: =COUNTIFS(TestCase!$A:$A,A13,TestCase!$G:$G,$C$5) -> 4 | D13: =COUNTIFS(TestCase!$A:$A,A13,TestCase!$G:$G,$D$5) -> 0 | E13: =COUNTIFS(TestCase!$A:$A,A13,TestCase!$G:$G,$E$5) -> 0 | F13: =COUNTIFS(TestCase!$A:$A,A13,TestCase!$G:$G,$F$5) -> 0 | G13: =COUNTIFS(TestCase!$A:$A,A13,TestCase!$G:$G,$G$5) -> 0 | H13: =COUNTIFS(TestCase!$A:$A,A13,TestCase!$G:$G,$H$5) -> 0 | I13: =COUNTIFS(TestCase!$A:$A,A13,TestCase!$G:$G,$I$5) -> 0 | J13: =SUM(C13:H13) -> 4 | K13: =IFERROR(ROUND(C13/J13,4),0) -> 1 | L13: =IFERROR(ROUND(D13/J13,4),0) -> 0 | M13: =IFERROR(ROUND(E13/J13,4),0) -> 0 | N13: =IFERROR(ROUND(F13/J13,4),0) -> 0 | O13: =IFERROR(ROUND(G13/J13,4),0) -> 0 | P13: =IFERROR(ROUND(H13/J13,4),0) -> 0
A14: DPT_003 | B14: DPT_APPROVE_MODIFY: Approve modify deposit account | C14: =COUNTIFS(TestCase!$A:$A,A14,TestCase!$G:$G,$C$5) -> 45 | D14: =COUNTIFS(TestCase!$A:$A,A14,TestCase!$G:$G,$D$5) -> 0 | E14: =COUNTIFS(TestCase!$A:$A,A14,TestCase!$G:$G,$E$5) -> 0 | F14: =COUNTIFS(TestCase!$A:$A,A14,TestCase!$G:$G,$F$5) -> 0 | G14: =COUNTIFS(TestCase!$A:$A,A14,TestCase!$G:$G,$G$5) -> 0 | H14: =COUNTIFS(TestCase!$A:$A,A14,TestCase!$G:$G,$H$5) -> 0 | I14: =COUNTIFS(TestCase!$A:$A,A14,TestCase!$G:$G,$I$5) -> 0 | J14: =SUM(C14:H14) -> 45 | K14: =IFERROR(ROUND(C14/J14,4),0) -> 1 | L14: =IFERROR(ROUND(D14/J14,4),0) -> 0 | M14: =IFERROR(ROUND(E14/J14,4),0) -> 0 | N14: =IFERROR(ROUND(F14/J14,4),0) -> 0 | O14: =IFERROR(ROUND(G14/J14,4),0) -> 0 | P14: =IFERROR(ROUND(H14/J14,4),0) -> 0
A15: DPT_004 | B15: DPT_DELETE_ACCOUNTLINKAGE: Delete account linkage | C15: =COUNTIFS(TestCase!$A:$A,A15,TestCase!$G:$G,$C$5) -> 5 | D15: =COUNTIFS(TestCase!$A:$A,A15,TestCase!$G:$G,$D$5) -> 0 | E15: =COUNTIFS(TestCase!$A:$A,A15,TestCase!$G:$G,$E$5) -> 0 | F15: =COUNTIFS(TestCase!$A:$A,A15,TestCase!$G:$G,$F$5) -> 0 | G15: =COUNTIFS(TestCase!$A:$A,A15,TestCase!$G:$G,$G$5) -> 0 | H15: =COUNTIFS(TestCase!$A:$A,A15,TestCase!$G:$G,$H$5) -> 0 | I15: =COUNTIFS(TestCase!$A:$A,A15,TestCase!$G:$G,$I$5) -> 0 | J15: =SUM(C15:H15) -> 5 | K15: =IFERROR(ROUND(C15/J15,4),0) -> 1 | L15: =IFERROR(ROUND(D15/J15,4),0) -> 0 | M15: =IFERROR(ROUND(E15/J15,4),0) -> 0 | N15: =IFERROR(ROUND(F15/J15,4),0) -> 0 | O15: =IFERROR(ROUND(G15/J15,4),0) -> 0 | P15: =IFERROR(ROUND(H15/J15,4),0) -> 0
A16: Admin
A17: ADM_001 | B17: ADM_REFRESH_BRANCH: Refresh bank | C17: =COUNTIFS(TestCase!$A:$A,A17,TestCase!$G:$G,$C$5) -> 1 | D17: =COUNTIFS(TestCase!$A:$A,A17,TestCase!$G:$G,$D$5) -> 0 | E17: =COUNTIFS(TestCase!$A:$A,A17,TestCase!$G:$G,$E$5) -> 0 | F17: =COUNTIFS(TestCase!$A:$A,A17,TestCase!$G:$G,$F$5) -> 0 | G17: =COUNTIFS(TestCase!$A:$A,A17,TestCase!$G:$G,$G$5) -> 0 | H17: =COUNTIFS(TestCase!$A:$A,A17,TestCase!$G:$G,$H$5) -> 0 | I17: =COUNTIFS(TestCase!$A:$A,A17,TestCase!$G:$G,$I$5) -> 0 | J17: =SUM(C17:H17) -> 1 | K17: =IFERROR(ROUND(C17/J17,4),0) -> 1 | L17: =IFERROR(ROUND(D17/J17,4),0) -> 0 | M17: =IFERROR(ROUND(E17/J17,4),0) -> 0 | N17: =IFERROR(ROUND(F17/J17,4),0) -> 0 | O17: =IFERROR(ROUND(G17/J17,4),0) -> 0 | P17: =IFERROR(ROUND(H17/J17,4),0) -> 0
A18: ADM_002 | B18: ADM_REFRESH_BRANCH_BY_USER: Refresh branch | C18: =COUNTIFS(TestCase!$A:$A,A18,TestCase!$G:$G,$C$5) -> 1 | D18: =COUNTIFS(TestCase!$A:$A,A18,TestCase!$G:$G,$D$5) -> 0 | E18: =COUNTIFS(TestCase!$A:$A,A18,TestCase!$G:$G,$E$5) -> 0 | F18: =COUNTIFS(TestCase!$A:$A,A18,TestCase!$G:$G,$F$5) -> 0 | G18: =COUNTIFS(TestCase!$A:$A,A18,TestCase!$G:$G,$G$5) -> 0 | H18: =COUNTIFS(TestCase!$A:$A,A18,TestCase!$G:$G,$H$5) -> 0 | I18: =COUNTIFS(TestCase!$A:$A,A18,TestCase!$G:$G,$I$5) -> 0 | J18: =SUM(C18:H18) -> 1 | K18: =IFERROR(ROUND(C18/J18,4),0) -> 1 | L18: =IFERROR(ROUND(D18/J18,4),0) -> 0 | M18: =IFERROR(ROUND(E18/J18,4),0) -> 0 | N18: =IFERROR(ROUND(F18/J18,4),0) -> 0 | O18: =IFERROR(ROUND(G18/J18,4),0) -> 0 | P18: =IFERROR(ROUND(H18/J18,4),0) -> 0
A19: ADM_003 | B19: ADM_CLOSE_BRANCH: Close branch | C19: =COUNTIFS(TestCase!$A:$A,A19,TestCase!$G:$G,$C$5) -> 6 | D19: =COUNTIFS(TestCase!$A:$A,A19,TestCase!$G:$G,$D$5) -> 0 | E19: =COUNTIFS(TestCase!$A:$A,A19,TestCase!$G:$G,$E$5) -> 0 | F19: =COUNTIFS(TestCase!$A:$A,A19,TestCase!$G:$G,$F$5) -> 0 | G19: =COUNTIFS(TestCase!$A:$A,A19,TestCase!$G:$G,$G$5) -> 0 | H19: =COUNTIFS(TestCase!$A:$A,A19,TestCase!$G:$G,$H$5) -> 0 | I19: =COUNTIFS(TestCase!$A:$A,A19,TestCase!$G:$G,$I$5) -> 0 | J19: =SUM(C19:H19) -> 6 | K19: =IFERROR(ROUND(C19/J19,4),0) -> 1 | L19: =IFERROR(ROUND(D19/J19,4),0) -> 0 | M19: =IFERROR(ROUND(E19/J19,4),0) -> 0 | N19: =IFERROR(ROUND(F19/J19,4),0) -> 0 | O19: =IFERROR(ROUND(G19/J19,4),0) -> 0 | P19: =IFERROR(ROUND(H19/J19,4),0) -> 0
A20: ADM_004 | B20: ADM_OPEN_BRANCH: Open branch | C20: =COUNTIFS(TestCase!$A:$A,A20,TestCase!$G:$G,$C$5) -> 4 | D20: =COUNTIFS(TestCase!$A:$A,A20,TestCase!$G:$G,$D$5) -> 0 | E20: =COUNTIFS(TestCase!$A:$A,A20,TestCase!$G:$G,$E$5) -> 0 | F20: =COUNTIFS(TestCase!$A:$A,A20,TestCase!$G:$G,$F$5) -> 0 | G20: =COUNTIFS(TestCase!$A:$A,A20,TestCase!$G:$G,$G$5) -> 0 | H20: =COUNTIFS(TestCase!$A:$A,A20,TestCase!$G:$G,$H$5) -> 0 | I20: =COUNTIFS(TestCase!$A:$A,A20,TestCase!$G:$G,$I$5) -> 0 | J20: =SUM(C20:H20) -> 4 | K20: =IFERROR(ROUND(C20/J20,4),0) -> 1 | L20: =IFERROR(ROUND(D20/J20,4),0) -> 0 | M20: =IFERROR(ROUND(E20/J20,4),0) -> 0 | N20: =IFERROR(ROUND(F20/J20,4),0) -> 0 | O20: =IFERROR(ROUND(G20/J20,4),0) -> 0 | P20: =IFERROR(ROUND(H20/J20,4),0) -> 0
A21: ADM_005 | B21: ADM_ADVANCED_SEARCH_ROLE_OF_USER: Role Profile - User - Assignment | C21: =COUNTIFS(TestCase!$A:$A,A21,TestCase!$G:$G,$C$5) -> 3 | D21: =COUNTIFS(TestCase!$A:$A,A21,TestCase!$G:$G,$D$5) -> 0 | E21: =COUNTIFS(TestCase!$A:$A,A21,TestCase!$G:$G,$E$5) -> 0 | F21: =COUNTIFS(TestCase!$A:$A,A21,TestCase!$G:$G,$F$5) -> 0 | G21: =COUNTIFS(TestCase!$A:$A,A21,TestCase!$G:$G,$G$5) -> 0 | H21: =COUNTIFS(TestCase!$A:$A,A21,TestCase!$G:$G,$H$5) -> 0 | I21: =COUNTIFS(TestCase!$A:$A,A21,TestCase!$G:$G,$I$5) -> 0 | J21: =SUM(C21:H21) -> 3 | K21: =IFERROR(ROUND(C21/J21,4),0) -> 1 | L21: =IFERROR(ROUND(D21/J21,4),0) -> 0 | M21: =IFERROR(ROUND(E21/J21,4),0) -> 0 | N21: =IFERROR(ROUND(F21/J21,4),0) -> 0 | O21: =IFERROR(ROUND(G21/J21,4),0) -> 0 | P21: =IFERROR(ROUND(H21/J21,4),0) -> 0
A22: ADM_006 | B22: ADM_SIMPLE_SEARCH_USER_ACCOUNT: Search common user profile | C22: =COUNTIFS(TestCase!$A:$A,A22,TestCase!$G:$G,$C$5) -> 4 | D22: =COUNTIFS(TestCase!$A:$A,A22,TestCase!$G:$G,$D$5) -> 0 | E22: =COUNTIFS(TestCase!$A:$A,A22,TestCase!$G:$G,$E$5) -> 0 | F22: =COUNTIFS(TestCase!$A:$A,A22,TestCase!$G:$G,$F$5) -> 0 | G22: =COUNTIFS(TestCase!$A:$A,A22,TestCase!$G:$G,$G$5) -> 0 | H22: =COUNTIFS(TestCase!$A:$A,A22,TestCase!$G:$G,$H$5) -> 0 | I22: =COUNTIFS(TestCase!$A:$A,A22,TestCase!$G:$G,$I$5) -> 0 | J22: =SUM(C22:H22) -> 4 | K22: =IFERROR(ROUND(C22/J22,4),0) -> 1 | L22: =IFERROR(ROUND(D22/J22,4),0) -> 0 | M22: =IFERROR(ROUND(E22/J22,4),0) -> 0 | N22: =IFERROR(ROUND(F22/J22,4),0) -> 0 | O22: =IFERROR(ROUND(G22/J22,4),0) -> 0 | P22: =IFERROR(ROUND(H22/J22,4),0) -> 0
A23: ADM_007 | B23: ADM_UPDATE_LIST_USER_RIGHT: Role Profile - Invoke - Approve | C23: =COUNTIFS(TestCase!$A:$A,A23,TestCase!$G:$G,$C$5) -> 7 | D23: =COUNTIFS(TestCase!$A:$A,A23,TestCase!$G:$G,$D$5) -> 0 | E23: =COUNTIFS(TestCase!$A:$A,A23,TestCase!$G:$G,$E$5) -> 0 | F23: =COUNTIFS(TestCase!$A:$A,A23,TestCase!$G:$G,$F$5) -> 0 | G23: =COUNTIFS(TestCase!$A:$A,A23,TestCase!$G:$G,$G$5) -> 0 | H23: =COUNTIFS(TestCase!$A:$A,A23,TestCase!$G:$G,$H$5) -> 0 | I23: =COUNTIFS(TestCase!$A:$A,A23,TestCase!$G:$G,$I$5) -> 0 | J23: =SUM(C23:H23) -> 7 | K23: =IFERROR(ROUND(C23/J23,4),0) -> 1 | L23: =IFERROR(ROUND(D23/J23,4),0) -> 0 | M23: =IFERROR(ROUND(E23/J23,4),0) -> 0 | N23: =IFERROR(ROUND(F23/J23,4),0) -> 0 | O23: =IFERROR(ROUND(G23/J23,4),0) -> 0 | P23: =IFERROR(ROUND(H23/J23,4),0) -> 0
A24: ADM_008 | B24: SQL_SIMPLE_SEARCH_TRANSACTION_JOURNAL: Search common F8 | C24: =COUNTIFS(TestCase!$A:$A,A24,TestCase!$G:$G,$C$5) -> 6 | D24: =COUNTIFS(TestCase!$A:$A,A24,TestCase!$G:$G,$D$5) -> 0 | E24: =COUNTIFS(TestCase!$A:$A,A24,TestCase!$G:$G,$E$5) -> 3 | F24: =COUNTIFS(TestCase!$A:$A,A24,TestCase!$G:$G,$F$5) -> 0 | G24: =COUNTIFS(TestCase!$A:$A,A24,TestCase!$G:$G,$G$5) -> 0 | H24: =COUNTIFS(TestCase!$A:$A,A24,TestCase!$G:$G,$H$5) -> 0 | I24: =COUNTIFS(TestCase!$A:$A,A24,TestCase!$G:$G,$I$5) -> 0 | J24: =SUM(C24:H24) -> 9 | K24: =IFERROR(ROUND(C24/J24,4),0) -> 0.6667 | L24: =IFERROR(ROUND(D24/J24,4),0) -> 0 | M24: =IFERROR(ROUND(E24/J24,4),0) -> 0.3333 | N24: =IFERROR(ROUND(F24/J24,4),0) -> 0 | O24: =IFERROR(ROUND(G24/J24,4),0) -> 0 | P24: =IFERROR(ROUND(H24/J24,4),0) -> 0
A25: ADM_009 | B25: SQL_ADVANCED_SEARCH_TRANSACTION_JOURNAL: Search advanced F8 | C25: =COUNTIFS(TestCase!$A:$A,A25,TestCase!$G:$G,$C$5) -> 6 | D25: =COUNTIFS(TestCase!$A:$A,A25,TestCase!$G:$G,$D$5) -> 0 | E25: =COUNTIFS(TestCase!$A:$A,A25,TestCase!$G:$G,$E$5) -> 3 | F25: =COUNTIFS(TestCase!$A:$A,A25,TestCase!$G:$G,$F$5) -> 0 | G25: =COUNTIFS(TestCase!$A:$A,A25,TestCase!$G:$G,$G$5) -> 0 | H25: =COUNTIFS(TestCase!$A:$A,A25,TestCase!$G:$G,$H$5) -> 0 | I25: =COUNTIFS(TestCase!$A:$A,A25,TestCase!$G:$G,$I$5) -> 0 | J25: =SUM(C25:H25) -> 9 | K25: =IFERROR(ROUND(C25/J25,4),0) -> 0.6667 | L25: =IFERROR(ROUND(D25/J25,4),0) -> 0 | M25: =IFERROR(ROUND(E25/J25,4),0) -> 0.3333 | N25: =IFERROR(ROUND(F25/J25,4),0) -> 0 | O25: =IFERROR(ROUND(G25/J25,4),0) -> 0 | P25: =IFERROR(ROUND(H25/J25,4),0) -> 0
A26: Payment
A27: PMT_001 | B27: PMT_SEARCH_SP_QUEUE_INWAR: Search common "Payment Queue for Inward" | C27: =COUNTIFS(TestCase!$A:$A,A27,TestCase!$G:$G,$C$5) -> 5 | D27: =COUNTIFS(TestCase!$A:$A,A27,TestCase!$G:$G,$D$5) -> 0 | E27: =COUNTIFS(TestCase!$A:$A,A27,TestCase!$G:$G,$E$5) -> 0 | F27: =COUNTIFS(TestCase!$A:$A,A27,TestCase!$G:$G,$F$5) -> 0 | G27: =COUNTIFS(TestCase!$A:$A,A27,TestCase!$G:$G,$G$5) -> 0 | H27: =COUNTIFS(TestCase!$A:$A,A27,TestCase!$G:$G,$H$5) -> 0 | I27: =COUNTIFS(TestCase!$A:$A,A27,TestCase!$G:$G,$I$5) -> 0 | J27: =SUM(C27:H27) -> 5 | K27: =IFERROR(ROUND(C27/J27,4),0) -> 1 | L27: =IFERROR(ROUND(D27/J27,4),0) -> 0 | M27: =IFERROR(ROUND(E27/J27,4),0) -> 0 | N27: =IFERROR(ROUND(F27/J27,4),0) -> 0 | O27: =IFERROR(ROUND(G27/J27,4),0) -> 0 | P27: =IFERROR(ROUND(H27/J27,4),0) -> 0
A28: Accounting
A29: ACT_001 | B29: ACT_ACCHRT_SER_SIMPLE: Search common "Bank Account Definition" | C29: =COUNTIFS(TestCase!$A:$A,A29,TestCase!$G:$G,$C$5) -> 5 | D29: =COUNTIFS(TestCase!$A:$A,A29,TestCase!$G:$G,$D$5) -> 0 | E29: =COUNTIFS(TestCase!$A:$A,A29,TestCase!$G:$G,$E$5) -> 0 | F29: =COUNTIFS(TestCase!$A:$A,A29,TestCase!$G:$G,$F$5) -> 0 | G29: =COUNTIFS(TestCase!$A:$A,A29,TestCase!$G:$G,$G$5) -> 0 | H29: =COUNTIFS(TestCase!$A:$A,A29,TestCase!$G:$G,$H$5) -> 0 | I29: =COUNTIFS(TestCase!$A:$A,A29,TestCase!$G:$G,$I$5) -> 0 | J29: =SUM(C29:H29) -> 5 | K29: =IFERROR(ROUND(C29/J29,4),0) -> 1 | L29: =IFERROR(ROUND(D29/J29,4),0) -> 0 | M29: =IFERROR(ROUND(E29/J29,4),0) -> 0 | N29: =IFERROR(ROUND(F29/J29,4),0) -> 0 | O29: =IFERROR(ROUND(G29/J29,4),0) -> 0 | P29: =IFERROR(ROUND(H29/J29,4),0) -> 0
A30: ACT_002 | B30: ACT_ACCHRT_INS: Add "Bank Account Definition" | C30: =COUNTIFS(TestCase!$A:$A,A30,TestCase!$G:$G,$C$5) -> 11 | D30: =COUNTIFS(TestCase!$A:$A,A30,TestCase!$G:$G,$D$5) -> 0 | E30: =COUNTIFS(TestCase!$A:$A,A30,TestCase!$G:$G,$E$5) -> 0 | F30: =COUNTIFS(TestCase!$A:$A,A30,TestCase!$G:$G,$F$5) -> 0 | G30: =COUNTIFS(TestCase!$A:$A,A30,TestCase!$G:$G,$G$5) -> 0 | H30: =COUNTIFS(TestCase!$A:$A,A30,TestCase!$G:$G,$H$5) -> 0 | I30: =COUNTIFS(TestCase!$A:$A,A30,TestCase!$G:$G,$I$5) -> 0 | J30: =SUM(C30:H30) -> 11 | K30: =IFERROR(ROUND(C30/J30,4),0) -> 1 | L30: =IFERROR(ROUND(D30/J30,4),0) -> 0 | M30: =IFERROR(ROUND(E30/J30,4),0) -> 0 | N30: =IFERROR(ROUND(F30/J30,4),0) -> 0 | O30: =IFERROR(ROUND(G30/J30,4),0) -> 0 | P30: =IFERROR(ROUND(H30/J30,4),0) -> 0
A31: Treasury
A32: TRS_001 | B32: TRS_SEARCH_ACCOUNT: Search common "Treasury account information" | C32: =COUNTIFS(TestCase!$A:$A,A32,TestCase!$G:$G,$C$5) -> 5 | D32: =COUNTIFS(TestCase!$A:$A,A32,TestCase!$G:$G,$D$5) -> 0 | E32: =COUNTIFS(TestCase!$A:$A,A32,TestCase!$G:$G,$E$5) -> 0 | F32: =COUNTIFS(TestCase!$A:$A,A32,TestCase!$G:$G,$F$5) -> 0 | G32: =COUNTIFS(TestCase!$A:$A,A32,TestCase!$G:$G,$G$5) -> 0 | H32: =COUNTIFS(TestCase!$A:$A,A32,TestCase!$G:$G,$H$5) -> 0 | I32: =COUNTIFS(TestCase!$A:$A,A32,TestCase!$G:$G,$I$5) -> 0 | J32: =SUM(C32:H32) -> 5 | K32: =IFERROR(ROUND(C32/J32,4),0) -> 1 | L32: =IFERROR(ROUND(D32/J32,4),0) -> 0 | M32: =IFERROR(ROUND(E32/J32,4),0) -> 0 | N32: =IFERROR(ROUND(F32/J32,4),0) -> 0 | O32: =IFERROR(ROUND(G32/J32,4),0) -> 0 | P32: =IFERROR(ROUND(H32/J32,4),0) -> 0
A33: TRS_002 | B33: TRS_VIEW_ACCOUNT: View "Treasury account information" | C33: =COUNTIFS(TestCase!$A:$A,A33,TestCase!$G:$G,$C$5) -> 2 | D33: =COUNTIFS(TestCase!$A:$A,A33,TestCase!$G:$G,$D$5) -> 0 | E33: =COUNTIFS(TestCase!$A:$A,A33,TestCase!$G:$G,$E$5) -> 0 | F33: =COUNTIFS(TestCase!$A:$A,A33,TestCase!$G:$G,$F$5) -> 0 | G33: =COUNTIFS(TestCase!$A:$A,A33,TestCase!$G:$G,$G$5) -> 0 | H33: =COUNTIFS(TestCase!$A:$A,A33,TestCase!$G:$G,$H$5) -> 0 | I33: =COUNTIFS(TestCase!$A:$A,A33,TestCase!$G:$G,$I$5) -> 0 | J33: =SUM(C33:H33) -> 2 | K33: =IFERROR(ROUND(C33/J33,4),0) -> 1 | L33: =IFERROR(ROUND(D33/J33,4),0) -> 0 | M33: =IFERROR(ROUND(E33/J33,4),0) -> 0 | N33: =IFERROR(ROUND(F33/J33,4),0) -> 0 | O33: =IFERROR(ROUND(G33/J33,4),0) -> 0 | P33: =IFERROR(ROUND(H33/J33,4),0) -> 0
A34: Credit
A35: CRD_001 | B35: CRD_SEARCH_SP_CREDIT: Search common "Credit account information" | C35: =COUNTIFS(TestCase!$A:$A,A35,TestCase!$G:$G,$C$5) -> 0 | D35: =COUNTIFS(TestCase!$A:$A,A35,TestCase!$G:$G,$D$5) -> 0 | E35: =COUNTIFS(TestCase!$A:$A,A35,TestCase!$G:$G,$E$5) -> 0 | F35: =COUNTIFS(TestCase!$A:$A,A35,TestCase!$G:$G,$F$5) -> 0 | G35: =COUNTIFS(TestCase!$A:$A,A35,TestCase!$G:$G,$G$5) -> 0 | H35: =COUNTIFS(TestCase!$A:$A,A35,TestCase!$G:$G,$H$5) -> 0 | I35: =COUNTIFS(TestCase!$A:$A,A35,TestCase!$G:$G,$I$5) -> 0 | J35: =SUM(C35:H35) -> 0 | K35: =IFERROR(ROUND(C35/J35,4),0) -> 0 | L35: =IFERROR(ROUND(D35/J35,4),0) -> 0 | M35: =IFERROR(ROUND(E35/J35,4),0) -> 0 | N35: =IFERROR(ROUND(F35/J35,4),0) -> 0 | O35: =IFERROR(ROUND(G35/J35,4),0) -> 0 | P35: =IFERROR(ROUND(H35/J35,4),0) -> 0
A36: CRD_002 | B36: CRD_VIEW_CREDIT: View "Credit account information" | C36: =COUNTIFS(TestCase!$A:$A,A36,TestCase!$G:$G,$C$5) -> 0 | D36: =COUNTIFS(TestCase!$A:$A,A36,TestCase!$G:$G,$D$5) -> 0 | E36: =COUNTIFS(TestCase!$A:$A,A36,TestCase!$G:$G,$E$5) -> 0 | F36: =COUNTIFS(TestCase!$A:$A,A36,TestCase!$G:$G,$F$5) -> 0 | G36: =COUNTIFS(TestCase!$A:$A,A36,TestCase!$G:$G,$G$5) -> 0 | H36: =COUNTIFS(TestCase!$A:$A,A36,TestCase!$G:$G,$H$5) -> 0 | I36: =COUNTIFS(TestCase!$A:$A,A36,TestCase!$G:$G,$I$5) -> 0 | J36: =SUM(C36:H36) -> 0 | K36: =IFERROR(ROUND(C36/J36,4),0) -> 0 | L36: =IFERROR(ROUND(D36/J36,4),0) -> 0 | M36: =IFERROR(ROUND(E36/J36,4),0) -> 0 | N36: =IFERROR(ROUND(F36/J36,4),0) -> 0 | O36: =IFERROR(ROUND(G36/J36,4),0) -> 0 | P36: =IFERROR(ROUND(H36/J36,4),0) -> 0
A37: Foreign Exchange Rate
A38: FXR_001 | B38: FX_FXRATE_GETFXRATE: View "Foreign Exchange Rate" | C38: =COUNTIFS(TestCase!$A:$A,A38,TestCase!$G:$G,$C$5) -> 2 | D38: =COUNTIFS(TestCase!$A:$A,A38,TestCase!$G:$G,$D$5) -> 0 | E38: =COUNTIFS(TestCase!$A:$A,A38,TestCase!$G:$G,$E$5) -> 0 | F38: =COUNTIFS(TestCase!$A:$A,A38,TestCase!$G:$G,$F$5) -> 0 | G38: =COUNTIFS(TestCase!$A:$A,A38,TestCase!$G:$G,$G$5) -> 0 | H38: =COUNTIFS(TestCase!$A:$A,A38,TestCase!$G:$G,$H$5) -> 0 | I38: =COUNTIFS(TestCase!$A:$A,A38,TestCase!$G:$G,$I$5) -> 0 | J38: =SUM(C38:H38) -> 2 | K38: =IFERROR(ROUND(C38/J38,4),0) -> 1 | L38: =IFERROR(ROUND(D38/J38,4),0) -> 0 | M38: =IFERROR(ROUND(E38/J38,4),0) -> 0 | N38: =IFERROR(ROUND(F38/J38,4),0) -> 0 | O38: =IFERROR(ROUND(G38/J38,4),0) -> 0 | P38: =IFERROR(ROUND(H38/J38,4),0) -> 0
A39: Total | C39: =SUM(C7:C38) -> 204 | D39: =SUM(D7:D38) -> 0 | E39: =SUM(E7:E38) -> 6 | F39: =SUM(F7:F38) -> 0 | G39: =SUM(G7:G38) -> 0 | H39: =SUM(H7:H38) -> 0 | I39: =SUM(I7:I38) -> 0 | J39: =SUM(J7:J38) -> 210 | K39: =IFERROR(100%-SUM(L39:P39),0) -> 0.9714 | L39: =IFERROR(ROUND(D39/$J$39,4),0) -> 0 | M39: =IFERROR(ROUND(E39/$J$39,4),0) -> 0.0286 | N39: =IFERROR(ROUND(F39/$J$39,4),0) -> 0 | O39: =IFERROR(ROUND(G39/$J$39,4),0) -> 0 | P39: =IFERROR(ROUND(H39/$J$39,4),0) -> 0
A41: Remark: Status of Test Scenario on section “Overall Status”:
A42: - Passed = Test Scenario has been tested as planned and application works as expected result.
A43: - Failed = Test Scenario has been tested as planned but application does not work as expected.
A44: - Blocked = Test Scenario could not be tested as planned because there is an outstanding defect in related function area.
...

Sheet TestCase
A2: TEST CASES
A3: Environment:
A5: Scenario ID | B5: Scenario name | C5: Test case ID | D5: Test condition ID | E5: Condition | F5: Expected Result | G5: Result | H5: Comments | I5: Create date | J5: Test lần 1 | K5: Test lần 2 | L5: Executor | M5: Editor | N5: Update date
A6: CTM_001 | B6: =VLOOKUP(TestCase!A6,'Scenario Test'!$A$5:$B$135,2,0) -> SQL_INSERT_CTM: Add customer profile
A7: CTM_001 | B7: =VLOOKUP(TestCase!A7,'Scenario Test'!$A$5:$B$135,2,0) -> SQL_INSERT_CTM: Add customer profile | C7: CTM_001_001 | E7: Add C1: Personal customer | F7: Add successfully - Address - Extension fields - "LastModifyUserCode" get value is UserCode login Auto insert data into "Customer Linkage" Check data in the tables: - o9customer.dbo.SingleCustomer - o9customer.dbo.CustomerLinkage - o9customer.dbo.CustomerExtension - o9customer.dbo.CustomerAlias | G7: Pass | I7: 45659 | J7: 45660 | K7: 45665 | L7: NhiDY
A8: CTM_001 | B8: =VLOOKUP(TestCase!A8,'Scenario Test'!$A$5:$B$135,2,0) -> SQL_INSERT_CTM: Add customer profile | C8: CTM_001_002 | E8: Add C2: SME customer | F8: Add successfully - Address - Extension fields - "LastModifyUserCode" get value is UserCode login Insert data into "Customer Group" Check data in the tables: - o9customer.dbo.SingleCustomer - o9customer.dbo.CustomerGroup - o9customer.dbo.CustomerExtension - o9customer.dbo.CustomerAlias | G8: Pass | I8: 45659 | J8: 45660 | K8: 45665 | L8: NhiDY
A9: CTM_001 | B9: =VLOOKUP(TestCase!A9,'Scenario Test'!$A$5:$B$135,2,0) -> SQL_INSERT_CTM: Add customer profile | C9: CTM_001_003 | E9: Add C3: Corporate customer | F9: Add successfully - Address - Extension fields - "LastModifyUserCode" get value is UserCode login Insert data into "Customer Group" Check data in the tables: - o9customer.dbo.SingleCustomer - o9customer.dbo.CustomerGroup - o9customer.dbo.CustomerExtension - o9customer.dbo.CustomerAlias | G9: Pass | I9: 45659 | J9: 45660 | K9: 45665 | L9: NhiDY
A10: CTM_001 | B10: =VLOOKUP(TestCase!A10,'Scenario Test'!$A$5:$B$135,2,0) -> SQL_INSERT_CTM: Add customer profile | C10: CTM_001_004 | E10: Add C4: Institutional customer | F10: Add successfully - Address - Extension fields - "LastModifyUserCode" get value is UserCode login Insert data into "Customer Group" Check data in the tables: - o9customer.dbo.SingleCustomer - o9customer.dbo.CustomerGroup - o9customer.dbo.CustomerExtension - o9customer.dbo.CustomerAlias | G10: Pass | I10: 45659 | J10: 45660 | K10: 45665 | L10: NhiDY
A11: CTM_001 | B11: =VLOOKUP(TestCase!A11,'Scenario Test'!$A$5:$B$135,2,0) -> SQL_INSERT_CTM: Add customer profile | C11: CTM_001_005 | E11: Update customer have extension fields with: - Reason For Other Economic Sector: empty - Reason For Other Business Type: empty - Referral Field: empty - Reason For Other Sub Economic Sector: empty - Reason For Other Occupation: empty - Reason For Other Paper Type: empty - Income: empty - Introducer: empty - Position: empty - Remark Field To Add: empty - Employer Name: empty - Fdi Info: empty - Tin Number: empty | F11: Add successfully - Insert data into table "CustomerExtension" | G11: Pass | I11: 45659 | J11: 45660 | K11: 45665 | L11: NhiDY
A12: CTM_001 | B12: =VLOOKUP(TestCase!A12,'Scenario Test'!$A$5:$B$135,2,0) -> SQL_INSERT_CTM: Add customer profile | C12: CTM_001_006 | E12: Add customer with address containing special characters | F12: Add successfully - Address - Extension fields - "LastModifyUserCode" get value is UserCode login | G12: Pass | I12: 45659 | J12: 45665 | L12: NhiDY
A13: CTM_001 | B13: =VLOOKUP(TestCase!A13,'Scenario Test'!$A$5:$B$135,2,0) -> SQL_INSERT_CTM: Add customer profile | C13: CTM_001_007 | E13: Add customer with existing "Paper number" and "Paper type" | F13: Add fail Error message "ERROR: Paper number existed" | G13: Pass | I13: 45659 | L13: NhiDY
A14: CTM_002 | B14: =VLOOKUP(TestCase!A14,'Scenario Test'!$A$5:$B$135,2,0) -> SQL_UPDATE_CTM: Update customer profile
A15: CTM_002 | B15: =VLOOKUP(TestCase!A15,'Scenario Test'!$A$5:$B$135,2,0) -> SQL_UPDATE_CTM: Update customer profile | C15: CTM_002_001 | E15: Update C1: Personal customer - Status is "Pending to approve" | F15: Modify successfully, NO need to approve - Address - Extension fields - "LastModifyUserCode" get UserCode of user login and make update - "UpdatedOnUtc" get date and time UTC | G15: Pass | I15: 45659 | J15: 45663 | K15: 45665 | L15: NhiDY
A16: CTM_002 | B16: =VLOOKUP(TestCase!A16,'Scenario Test'!$A$5:$B$135,2,0) -> SQL_UPDATE_CTM: Update customer profile | C16: CTM_002_002 | E16: Update C1: Personal customer - Status is "Normal" or "Block" or "Decease Claim" or "Closed" | F16: Modify successfully, need to approve - Address - Extension fields - "LastModifyUserCode" get UserCode of user login and make update - "UpdatedOnUtc" get date and time UTC - "LastUpdateDate" get real date | G16: Pass | I16: 45659 | J16: 45663 | K16: 45665 | L16: NhiDY
A17: CTM_002 | B17: =VLOOKUP(TestCase!A17,'Scenario Test'!$A$5:$B$135,2,0) -> SQL_UPDATE_CTM: Update customer profile | C17: CTM_002_003 | E17: Update C2: SME customer - Status is "Pending to approve" | F17: Modify successfully, NO need to approve - Address - Extension fields - "LastModifyUserCode" get UserCode of user login and make update - "UpdatedOnUtc" get date and time UTC - "LastUpdateDate" get working date | G17: Pass | I17: 45659 | J17: 45663 | K17: 45665 | L17: NhiDY
A18: CTM_002 | B18: =VLOOKUP(TestCase!A18,'Scenario Test'!$A$5:$B$135,2,0) -> SQL_UPDATE_CTM: Update customer profile | C18: CTM_002_004 | E18: Update C2: SME customer - Status is "Normal" or "Block" or "Decease Claim" or "Closed" | F18: Modify successfully, need to approve - Address - Extension fields - "LastModifyUserCode" get UserCode of user login and make update - "UpdatedOnUtc" get date and time UTC - "LastUpdateDate" get working date | G18: Pass | I18: 45659 | J18: 45663 | K18: 45665 | L18: NhiDY
A19: CTM_002 | B19: =VLOOKUP(TestCase!A19,'Scenario Test'!$A$5:$B$135,2,0) -> SQL_UPDATE_CTM: Update customer profile | C19: CTM_002_005 | E19: Update C3: Corporate customer - Status is "Pending to approve" | F19: Modify successfully, NO need to approve - Address - Extension fields - "LastModifyUserCode" get UserCode of user login and make update - "UpdatedOnUtc" get date and time UTC - "LastUpdateDate" get working date | G19: Pass | I19: 45659 | J19: 45663 | K19: 45665 | L19: NhiDY
A20: CTM_002 | B20: =VLOOKUP(TestCase!A20,'Scenario Test'!$A$5:$B$135,2,0) -> SQL_UPDATE_CTM: Update customer profile | C20: CTM_002_006 | E20: Update C3: Corporate customer - Status is "Normal" or "Block" or "Decease Claim" or "Closed" | F20: Modify successfully, need to approve - Address - Extension fields - "LastModifyUserCode" get UserCode of user login and make update - "UpdatedOnUtc" get date and time UTC - "LastUpdateDate" get working date | G20: Pass | I20: 45659 | J20: 45663 | K20: 45665 | L20: NhiDY
A21: CTM_002 | B21: =VLOOKUP(TestCase!A21,'Scenario Test'!$A$5:$B$135,2,0) -> SQL_UPDATE_CTM: Update customer profile | C21: CTM_002_007 | E21: Update C4: Institutional customer - Status is "Pending to approve" | F21: Modify successfully, NO need to approve - Address - Extension fields - "LastModifyUserCode" get UserCode of user login and make update - "UpdatedOnUtc" get date and time UTC - "LastUpdateDate" get working date | G21: Pass | I21: 45659 | J21: 45663 | K21: 45665 | L21: NhiDY
A22: CTM_002 | B22: =VLOOKUP(TestCase!A22,'Scenario Test'!$A$5:$B$135,2,0) -> SQL_UPDATE_CTM: Update customer profile | C22: CTM_002_008 | E22: Update C4: Institutional customer - Status is "Normal" or "Block" or "Decease Claim" or "Closed" | F22: Modify successfully, need to approve - Address - Extension fields - "LastModifyUserCode" get UserCode of user login and make update - "UpdatedOnUtc" get date and time UTC - "LastUpdateDate" get working date | G22: Pass | I22: 45659 | J22: 45663 | K22: 45665 | L22: NhiDY
A23: CTM_002 | B23: =VLOOKUP(TestCase!A23,'Scenario Test'!$A$5:$B$135,2,0) -> SQL_UPDATE_CTM: Update customer profile | C23: CTM_002_009 | E23: Update customer have extension fields with: - Reason For Other Economic Sector: empty - Reason For Other Business Type: empty - Referral Field: empty - Reason For Other Sub Economic Sector: empty - Reason For Other Occupation: empty - Reason For Other Paper Type: empty - Income: empty - Introducer: empty - Position: empty - Remark Field To Add: empty - Employer Name: empty - Fdi Info: empty - Tin Number: empty | F23: Modify successfully - Insert data into table "CustomerExtension" | G23: Pass | I23: 45659 | J23: 45665 | K23: 45665 | L23: NhiDY
A24: CTM_002 | B24: =VLOOKUP(TestCase!A24,'Scenario Test'!$A$5:$B$135,2,0) -> SQL_UPDATE_CTM: Update customer profile | C24: CTM_002_010 | E24: Update customer have relation account information | F24: Modify successfully | G24: Pass | I24: 45659 | J24: 45665 | L24: NhiDY
A25: CTM_002 | B25: =VLOOKUP(TestCase!A25,'Scenario Test'!$A$5:$B$135,2,0) -> SQL_UPDATE_CTM: Update customer profile | C25: CTM_002_011 | E25: Update customer with: - Status "Pending to approve" - Change paper number | F25: Popup is showed 'Modify successfully | G25: Pass | I25: 45659 | J25: 45665 | L25: NhiDY
A26: CTM_002 | B26: =VLOOKUP(TestCase!A26,'Scenario Test'!$A$5:$B$135,2,0) -> SQL_UPDATE_CTM: Update customer profile | C26: CTM_002_012 | E26: Update customer with extension field change from "Other" to NOT "Other": - Reason For Other Economic Sector - Reason For Other Business Type - Reason For Other Sub Economic Sector - Reason For Other Occupation - Reason For Other Paper Type | F26: Modify successfully - Data in "Other" field skipped, not clear data | G26: Pass | I26: 45659 | J26: 45665 | L26: NhiDY
A27: CTM_002 | B27: =VLOOKUP(TestCase!A27,'Scenario Test'!$A$5:$B$135,2,0) -> SQL_UPDATE_CTM: Update customer profile | C27: CTM_002_013 | E27: Update customer with address containing special characters | F27: Modify successfully | G27: Pass | I27: 45659 | J27: 45665 | L27: NhiDY
A28: CTM_002 | B28: =VLOOKUP(TestCase!A28,'Scenario Test'!$A$5:$B$135,2,0) -> SQL_UPDATE_CTM: Update customer profile | C28: CTM_002_014 | E28: Update customer with: - "Is Restricted" is null | F28: Modify successfully | G28: Pass | I28: 45659 | J28: 45665 | L28: NhiDY
A29: CTM_002 | B29: =VLOOKUP(TestCase!A29,'Scenario Test'!$A$5:$B$135,2,0) -> SQL_UPDATE_CTM: Update customer profile | C29: CTM_002_015 | E29: Update customer have NO extension fields with: - Reason For Other Economic Sector - Reason For Other Business Type - Referral Field - Reason For Other Sub Economic Sector - Reason For Other Occupation - Reason For Other Paper Type - Income - Introducer - Position - Remark Field To Add - Employer Name - Fdi Info - Tin Number Note: delete data in table "CustomerExtension" | F29: Modify successfully | G29: Pass | I29: 45659 | J29: 45665 | L29: NhiDY
A30: CTM_002 | B30: =VLOOKUP(TestCase!A30,'Scenario Test'!$A$5:$B$135,2,0) -> SQL_UPDATE_CTM: Update customer profile | C30: CTM_002_016 | E30: Update customer with "Relation Deposit Information": - Deposit account have "Balance" is ******** | F30: Modify successfully | G30: Pass | I30: 45659 | J30: 45665 | L30: NhiDY
A31: CTM_003 | B31: =VLOOKUP(TestCase!A31,'Scenario Test'!$A$5:$B$135,2,0) -> SQL_INSERT_MEDIA: Import media file
A32: CTM_003 | B32: =VLOOKUP(TestCase!A32,'Scenario Test'!$A$5:$B$135,2,0) -> SQL_INSERT_MEDIA: Import media file | C32: CTM_003_001 | E32: Import media file 2MB - PNG/JPG/PDF/Excel - Expired date is empty | F32: Import successfully - Insert data is correct - o9customer.dbo.CustomerMediaStorage - o9cms.dbo.MediaUpload - o9cms.dbo.UserMedia | G32: Pass | I32: 45659 | J32: 45664 | L32: NhiDY
A33: CTM_003 | B33: =VLOOKUP(TestCase!A33,'Scenario Test'!$A$5:$B$135,2,0) -> SQL_INSERT_MEDIA: Import media file | C33: CTM_003_002 | E33: Import media file 2MB - PNG/JPG/PDF/Excel - Expired date is valid | F33: Import successfully - Insert data is correct - o9customer.dbo.CustomerMediaStorage - o9cms.dbo.MediaUpload - o9cms.dbo.UserMedia | G33: Pass | I33: 45659 | J33: 45664 | L33: NhiDY
A34: CTM_003 | B34: =VLOOKUP(TestCase!A34,'Scenario Test'!$A$5:$B$135,2,0) -> SQL_INSERT_MEDIA: Import media file | C34: CTM_003_003 | E34: Import media file 5MB NOTE: update param Server "MEDIA_UPLOAD_MAX_SIZE" is "2" (mean: allow file with max size is 2MB) | F34: Import fail | G34: Pass | I34: 45659 | J34: 45664 | L34: NhiDY
A35: CTM_004 | B35: =VLOOKUP(TestCase!A35,'Scenario Test'!$A$5:$B$135,2,0) -> CTM_INSERT_CTM_API: OpenAPI add customer profile
A36: CTM_004 | B36: =VLOOKUP(TestCase!A36,'Scenario Test'!$A$5:$B$135,2,0) -> CTM_INSERT_CTM_API: OpenAPI add customer profile | C36: CTM_004_001 | E36: Using openAPI for third parties | F36: Add successfully - Address - Extension fields - "LastModifyUserCode" get value is UserCode login - Insert data into table "CustomerExtension" | G36: Pass | I36: 45659 | J36: 45665 | K36: 45665 | L36: NhiDY
A37: DPT_001 | B37: =VLOOKUP(TestCase!A37,'Scenario Test'!$A$5:$B$135,2,0) -> DPT_UPDATE_DEPOSIT: Modify deposit account
A38: DPT_001 | B38: =VLOOKUP(TestCase!A38,'Scenario Test'!$A$5:$B$135,2,0) -> DPT_UPDATE_DEPOSIT: Modify deposit account | C38: DPT_001_001 | E38: Update current account - Status is "Pending to approve" | F38: Modify successfully, NO need to approve | G38: Pass | I38: 45659 | J38: 45660 | K38: 45665 | L38: NhiDY
A39: DPT_001 | B39: =VLOOKUP(TestCase!A39,'Scenario Test'!$A$5:$B$135,2,0) -> DPT_UPDATE_DEPOSIT: Modify deposit account | C39: DPT_001_002 | E39: Update current account - Status is "New" | F39: Modify successfully, need to approve | G39: Pass | I39: 45659 | J39: 45660 | K39: 45665 | L39: NhiDY
A40: DPT_001 | B40: =VLOOKUP(TestCase!A40,'Scenario Test'!$A$5:$B$135,2,0) -> DPT_UPDATE_DEPOSIT: Modify deposit account | C40: DPT_001_003 | E40: Update current account - Status is "Normal" or "Block" or "Dormant" or "Closed" | F40: Modify successfully, need to approve | G40: Pass | I40: 45659 | J40: 45660 | K40: 45665 | L40: NhiDY
A41: DPT_001 | B41: =VLOOKUP(TestCase!A41,'Scenario Test'!$A$5:$B$135,2,0) -> DPT_UPDATE_DEPOSIT: Modify deposit account | C41: DPT_001_004 | E41: Update saving account - Status is "Pending to approve" | F41: Modify successfully, NO need to approve | G41: Pass | I41: 45659 | J41: 45660 | K41: 45665 | L41: NhiDY
A42: DPT_001 | B42: =VLOOKUP(TestCase!A42,'Scenario Test'!$A$5:$B$135,2,0) -> DPT_UPDATE_DEPOSIT: Modify deposit account | C42: DPT_001_005 | E42: Update saving account - Status is "New" | F42: Modify successfully, need to approve | G42: Pass | I42: 45659 | J42: 45660 | K42: 45665 | L42: NhiDY
...

Sheet C#

Sheet UpdateData
A1: Action | B1: Update data | C1: Update related table
C2: o9accounting | E2: o9admin | G2: o9cash | I2: o9deposit
C3: Table name | D3: Action | E3: Table name | F3: Action | G3: Table name | H3: Action | I3: Table name | J3: Action
A4: Deposit money for deposit account (current, saving, fixed deposit) | B4: Deposit account - Status: Normal (if prevoius status is New/ Dormant) - Increase Current balance, Available balance - Increase Deposit Amount, Week Credit, Month Credit, Quarter Credit, Semi - Annual Credit and Year Credit - BeginOfTenor = Working, EndOfTenor = Working date + tenor - LastChangeDormantToNormalDate (if previous status is Dormant) Deposit by cash - Increase Customer deposit, Total In, Closing balance of Cash flow Deposit by deposit - Decrease Current balance, Available balance - Increase Withdraw Amount, Week Debit, Month Debit, Quarter Debit, Semi - Annual Debit and Year Debit Deposit by GL - Decrease GL Balance | C4: GLEntries | D4: Insert new row | E4: TransactionJournalDone | F4: Insert new row | G4: CashList | H4: - CurrencyCode already existed: Update old row (update CurrentBalance) - CurrencyCode does not exist: Insert new row | I4: DepositAccount | J4: Update old row - DepositStatus (if prevoius status is New/ Dormant) - Psts - CurrentBalance, DepositAmount, WeekCredit, MonthCredit, QuarterCredit, SemiAnnualCredit, YearCredit - LastTransactionDate, UpdatedOnUtc - BeginOfTenor, EndOfTenor (if deposit type is Fixed Deposit) - LastChangeDormantToNormalDate (if previous status is Dormant) Update old row (if deposit by deposit) - Psts - CurrentBalance, WithdrawAmount, WeekDebit, MonthDebit, QuarterDebit, SemiAnnualDebit, YearDebit - LastTransactionDate, UpdatedOnUtc
C5: AccountBalance | D5: Update old row (update Balance) | E5: Transaction | F5: Insert new row | G5: CashStatement | H5: - CashierCode, CurrencyCode, CashType and ValueDate already existed: Update old row (update CashAmount) - CashierCode, CurrencyCode, CashType and ValueDate do not exist: Insert new row | I5: DepositStatement | J5: Insert new row
C6: AccountStatement | D6: Insert new row | E6: TransactionDetail | F6: Insert new row | G6: CashTransaction | H6: Insert new row | I6: DepositHistory | J6: Insert new row
C7: Transaction | D7: Insert new row | G7: GLEntries | H7: Insert new row | I7: DepositAccountTrans | J7: Insert new row
C8: TransactionDetail | D8: Insert new row | G8: Transaction | H8: Insert new row | I8: GLEntries | J8: Insert new row
G9: TransactionDetail | H9: Insert new row | I9: Transaction | J9: Insert new row
I10: TransactionDetail | J10: Insert new row
A11: Withdraw money for deposit account (current, saving) | B11: Deposit account - Decrease Current balance, Available balance - Increase Withdraw Amount, Week Debit, Month Debit, Quarter Debit, Semi - Annual Debit and Year Debit Withdraw by cash - Increase Customer withdrawal, Total Out, decrease Closing balance of Cash flow Withdraw by deposit - Increase Current balance, Available balance - Increase Deposit Amount, Week Credit, Month Credit, Quarter Credit, Semi - Annual Credit and Year Credit Withdraw by GL - Increase GL Balance | C11: GLEntries | D11: Insert new row | E11: TransactionJournalDone | F11: Insert new row | G11: CashList | H11: Update old row (update CurrentBalance) | I11: DepositAccount | J11: Update old row - DepositStatus (if prevoius status is New) - Psts - CurrentBalance, WithdrawAmount, WeekDebit, MonthDebit, QuarterDebit, SemiAnnualDebit, YearDebit - LastTransactionDate, UpdatedOnUtc - LastChangeDormantToNormalDate (if previous status is Dormant) Update old row (if withdraw by deposit) - DepositStatus (if prevoius status is New) - Psts - CurrentBalance, DepositAmount, WeekCredit, MonthCredit, QuarterCredit, SemiAnnualCredit, YearCredit - LastTransactionDate, UpdatedOnUtc
C12: AccountStatement | D12: Insert new row | E12: Transaction | F12: Insert new row | G12: CashStatement | H12: - CashierCode, CurrencyCode, CashType and ValueDate already existed: Update old row (update CashAmount) - CashierCode, CurrencyCode, CashType and ValueDate do not exist: Insert new row | I12: DepositStatement | J12: Insert new row
C13: Transaction | D13: Insert new row | E13: TransactionDetail | F13: Insert new row | G13: CashTransaction | H13: Insert new row | I13: DepositHistory | J13: Insert new row
C14: TransactionDetail | D14: Insert new row | G14: GLEntries | H14: Insert new row | I14: DepositAccountTrans | J14: Insert new row
G15: Transaction | H15: Insert new row | I15: GLEntries | J15: Insert new row
G16: TransactionDetail | H16: Insert new row | I16: Transaction | J16: Insert new row
I17: TransactionDetail | J17: Insert new row
A18: Deposit money for prepaid fixed deposit | B18: Fixed deposit account - Status: Normal (if prevoius status is New) - Increase Current balance, Available balance - Increase Deposit Amount, Week Credit, Month Credit, Quarter Credit, Semi - Annual Credit and Year Credit - BeginOfTenor = Working, EndOfTenor = Working date + tenor - Increase Interest prepaid Linkage account - Increase Current balance, Available balance - Increase Deposit Amount, Week Credit, Month Credit, Quarter Credit, Semi - Annual Credit and Year Credit Deposit by cash - Increase Customer deposit, Total In, Closing balance of Cash flow Deposit by deposit - Decrease Current balance, Available balance - Increase Withdraw Amount, Week Debit, Month Debit, Quarter Debit, Semi - Annual Debit and Year Debit | C18: GLEntries | D18: Insert new row | E18: TransactionJournalDone | F18: Insert new row | G18: CashList | H18: - CurrencyCode already existed: Update old row (update CurrentBalance) - CurrencyCode does not exist: Insert new row | I18: DepositAccount | J18: Update old row (Prepaid fixed deposit) - DepositStatus (if prevoius status is New) - Psts - CurrentBalance, DepositAmount, WeekCredit, MonthCredit, QuarterCredit, SemiAnnualCredit, YearCredit - LastTransactionDate, UpdatedOnUtc - BeginOfTenor, EndOfTenor (if deposit type is Fixed Deposit) - LastChangeDormantToNormalDate (if previous status is Dormant) Update old row (linkage account) - Psts - CurrentBalance, DepositAmount, WeekCredit, MonthCredit, QuarterCredit, SemiAnnualCredit, YearCredit - LastTransactionDate, UpdatedOnUtc Update old row (if deposit by deposit) - Psts - CurrentBalance, WithdrawAmount, WeekDebit, MonthDebit, QuarterDebit, SemiAnnualDebit, YearDebit - LastTransactionDate, UpdatedOnUtc
C19: AccountBalance | D19: Update old row (update Balance) | E19: Transaction | F19: Insert new row | G19: CashStatement | H19: Insert new row | I19: IFCBalance | J19: Update old row (update PrepaidAmount)
C20: AccountStatement | D20: Insert new row | E20: TransactionDetail | F20: Insert new row | G20: CashTransaction | H20: Insert new row | I20: IFCBalanceDetail | J20: Insert new row
C21: Transaction | D21: Insert new row | G21: GLEntries | H21: Insert new row | I21: DepositStatement | J21: Insert new row
C22: TransactionDetail | D22: Insert new row | G22: Transaction | H22: Insert new row | I22: DepositHistory | J22: Insert new row
G23: TransactionDetail | H23: Insert new row | I23: DepositAccountTrans | J23: Insert new row
I24: DepositIFCBalanceTrans | J24: Insert new row
I25: GLEntries | J25: Insert new row
I26: Transaction | J26: Insert new row
I27: TransactionDetail | J27: Insert new row
