Workbook
Name Pass: '[1]Test Case_ILC'!$H$13

Sheet Version
A4: CBS-SHWE_TC_C#toStore_DPT
D6: Version: 1.0
A7: Version history
A8: Version | B8: Maker | C8: Revision Date | D8: Checker | E8: Approval Date | F8: Document Changes
A9: 1 | B9: VyHNT | C9: 45614 | F9: Create document

Sheet Summary
B2: Bàn giao test case
B3: Ngày | C3: 43375
B4: Giờ | C4: 15h00
B5: Tổng số case | C5: ='Scenario Test'!J33 -> 352
B7: Execute test case lần 1 theo ngày
B8: Date Status | C8: 43374 | D8: 43375 | E8: 43376 | F8: 43377 | G8: 43378 | H8: 43379 | I8: 43380
B9: Pass
B10: Fail
B11: Block
B12: Pending
B13: Not Completed
B14: Actual execution
B15: Not yet execution
B17: Execute test case lần 2 theo ngày
B18: Date Status | C18: 43374 | D18: 43375 | E18: 43376 | F18: 43377 | G18: 43378 | H18: 43379 | I18: 43380
B19: Pass
B20: Fail
B21: Block
B22: Pending
B23: Not Completed
B24: Actual execution
B25: Not yet execution
B27: Percent execute test case
B28: Percent pass | C28: ='Scenario Test'!K33 -> 0
B29: Percent fail | C29: ='Scenario Test'!L33 -> 0
B30: Percent block | C30: ='Scenario Test'!N33 -> 0
B31: Percent pending | C31: ='Scenario Test'!O33 -> 0
B32: Percent not completed | C32: ='Scenario Test'!P33 -> 0
B33: Percent not run | C33: ='Scenario Test'!M33 -> 1
B35: Execute test case
B36: Pass | C36: ='Scenario Test'!C33 -> 0
B37: Fail | C37: ='Scenario Test'!D33 -> 0
B38: Block | C38: ='Scenario Test'!F33 -> 0
B39: Pending | C39: ='Scenario Test'!G33 -> 0
B40: Not Completed | C40: ='Scenario Test'!H33 -> 0
B41: Not run | C41: ='Scenario Test'!E33 -> 352

Sheet Scenario Test
A3: SUMMARY
A5: Scenario ID | B5: Scenario name | C5: Pass | D5: Fail | E5: + | F5: Block | G5: Pending | H5: Not Completed | I5: - | J5: Total | K5: Percent pass | L5: Percent fail | M5: Percent not run | N5: Percent block | O5: Percent pending | P5: Percent not completed | Q5: Remark
A6: Deposit transaction
A7: DPT_OPN | B7: Open new deposit account | C7: =COUNTIFS(TestCase!$A:$A,$A7,TestCase!$G:$G,C$5) -> 0 | D7: =COUNTIFS(TestCase!$A:$A,$A7,TestCase!$G:$G,D$5) -> 0 | E7: =COUNTIFS(TestCase!$A:$A,$A7,TestCase!$G:$G,E$5) -> 26 | F7: =COUNTIFS(TestCase!$A:$A,$A7,TestCase!$G:$G,F$5) -> 0 | G7: =COUNTIFS(TestCase!$A:$A,$A7,TestCase!$G:$G,G$5) -> 0 | H7: =COUNTIFS(TestCase!$A:$A,$A7,TestCase!$G:$G,H$5) -> 0 | I7: =COUNTIFS(TestCase!$A:$A,$A7,TestCase!$G:$G,I$5) -> 0 | J7: =SUM(C7:H7) -> 26 | K7: =IFERROR(ROUND(C7/J7,4),0) -> 0 | L7: =IFERROR(ROUND(D7/J7,4),0) -> 0 | M7: =IFERROR(ROUND(E7/J7,4),0) -> 1 | N7: =IFERROR(ROUND(F7/J7,4),0) -> 0 | O7: =IFERROR(ROUND(G7/J7,4),0) -> 0 | P7: =IFERROR(ROUND(H7/J7,4),0) -> 0
A8: DPT_APR | B8: Approve deposit account | C8: =COUNTIFS(TestCase!$A:$A,$A8,TestCase!$G:$G,C$5) -> 0 | D8: =COUNTIFS(TestCase!$A:$A,$A8,TestCase!$G:$G,D$5) -> 0 | E8: =COUNTIFS(TestCase!$A:$A,$A8,TestCase!$G:$G,E$5) -> 5 | F8: =COUNTIFS(TestCase!$A:$A,$A8,TestCase!$G:$G,F$5) -> 0 | G8: =COUNTIFS(TestCase!$A:$A,$A8,TestCase!$G:$G,G$5) -> 0 | H8: =COUNTIFS(TestCase!$A:$A,$A8,TestCase!$G:$G,H$5) -> 0 | I8: =COUNTIFS(TestCase!$A:$A,$A8,TestCase!$G:$G,I$5) -> 0 | J8: =SUM(C8:H8) -> 5 | K8: =IFERROR(ROUND(C8/J8,4),0) -> 0 | L8: =IFERROR(ROUND(D8/J8,4),0) -> 0 | M8: =IFERROR(ROUND(E8/J8,4),0) -> 1 | N8: =IFERROR(ROUND(F8/J8,4),0) -> 0 | O8: =IFERROR(ROUND(G8/J8,4),0) -> 0 | P8: =IFERROR(ROUND(H8/J8,4),0) -> 0
A9: DPT_REJ | B9: Reject deposit account | C9: =COUNTIFS(TestCase!$A:$A,$A9,TestCase!$G:$G,C$5) -> 0 | D9: =COUNTIFS(TestCase!$A:$A,$A9,TestCase!$G:$G,D$5) -> 0 | E9: =COUNTIFS(TestCase!$A:$A,$A9,TestCase!$G:$G,E$5) -> 4 | F9: =COUNTIFS(TestCase!$A:$A,$A9,TestCase!$G:$G,F$5) -> 0 | G9: =COUNTIFS(TestCase!$A:$A,$A9,TestCase!$G:$G,G$5) -> 0 | H9: =COUNTIFS(TestCase!$A:$A,$A9,TestCase!$G:$G,H$5) -> 0 | I9: =COUNTIFS(TestCase!$A:$A,$A9,TestCase!$G:$G,I$5) -> 0 | J9: =SUM(C9:H9) -> 4 | K9: =IFERROR(ROUND(C9/J9,4),0) -> 0 | L9: =IFERROR(ROUND(D9/J9,4),0) -> 0 | M9: =IFERROR(ROUND(E9/J9,4),0) -> 1 | N9: =IFERROR(ROUND(F9/J9,4),0) -> 0 | O9: =IFERROR(ROUND(G9/J9,4),0) -> 0 | P9: =IFERROR(ROUND(H9/J9,4),0) -> 0
A10: DPT_CDP | B10: Cash deposit | C10: =COUNTIFS(TestCase!$A:$A,$A10,TestCase!$G:$G,C$5) -> 0 | D10: =COUNTIFS(TestCase!$A:$A,$A10,TestCase!$G:$G,D$5) -> 0 | E10: =COUNTIFS(TestCase!$A:$A,$A10,TestCase!$G:$G,E$5) -> 22 | F10: =COUNTIFS(TestCase!$A:$A,$A10,TestCase!$G:$G,F$5) -> 0 | G10: =COUNTIFS(TestCase!$A:$A,$A10,TestCase!$G:$G,G$5) -> 0 | H10: =COUNTIFS(TestCase!$A:$A,$A10,TestCase!$G:$G,H$5) -> 0 | I10: =COUNTIFS(TestCase!$A:$A,$A10,TestCase!$G:$G,I$5) -> 0 | J10: =SUM(C10:H10) -> 22 | K10: =IFERROR(ROUND(C10/J10,4),0) -> 0 | L10: =IFERROR(ROUND(D10/J10,4),0) -> 0 | M10: =IFERROR(ROUND(E10/J10,4),0) -> 1 | N10: =IFERROR(ROUND(F10/J10,4),0) -> 0 | O10: =IFERROR(ROUND(G10/J10,4),0) -> 0 | P10: =IFERROR(ROUND(H10/J10,4),0) -> 0
A11: DPT_MDP | B11: Miscellaneous deposit | C11: =COUNTIFS(TestCase!$A:$A,$A11,TestCase!$G:$G,C$5) -> 0 | D11: =COUNTIFS(TestCase!$A:$A,$A11,TestCase!$G:$G,D$5) -> 0 | E11: =COUNTIFS(TestCase!$A:$A,$A11,TestCase!$G:$G,E$5) -> 27 | F11: =COUNTIFS(TestCase!$A:$A,$A11,TestCase!$G:$G,F$5) -> 0 | G11: =COUNTIFS(TestCase!$A:$A,$A11,TestCase!$G:$G,G$5) -> 0 | H11: =COUNTIFS(TestCase!$A:$A,$A11,TestCase!$G:$G,H$5) -> 0 | I11: =COUNTIFS(TestCase!$A:$A,$A11,TestCase!$G:$G,I$5) -> 0 | J11: =SUM(C11:H11) -> 27 | K11: =IFERROR(ROUND(C11/J11,4),0) -> 0 | L11: =IFERROR(ROUND(D11/J11,4),0) -> 0 | M11: =IFERROR(ROUND(E11/J11,4),0) -> 1 | N11: =IFERROR(ROUND(F11/J11,4),0) -> 0 | O11: =IFERROR(ROUND(G11/J11,4),0) -> 0 | P11: =IFERROR(ROUND(H11/J11,4),0) -> 0
A12: DPT_CWR | B12: Cash withdrawal | C12: =COUNTIFS(TestCase!$A:$A,$A12,TestCase!$G:$G,C$5) -> 0 | D12: =COUNTIFS(TestCase!$A:$A,$A12,TestCase!$G:$G,D$5) -> 0 | E12: =COUNTIFS(TestCase!$A:$A,$A12,TestCase!$G:$G,E$5) -> 14 | F12: =COUNTIFS(TestCase!$A:$A,$A12,TestCase!$G:$G,F$5) -> 0 | G12: =COUNTIFS(TestCase!$A:$A,$A12,TestCase!$G:$G,G$5) -> 0 | H12: =COUNTIFS(TestCase!$A:$A,$A12,TestCase!$G:$G,H$5) -> 0 | I12: =COUNTIFS(TestCase!$A:$A,$A12,TestCase!$G:$G,I$5) -> 0 | J12: =SUM(C12:H12) -> 14 | K12: =IFERROR(ROUND(C12/J12,4),0) -> 0 | L12: =IFERROR(ROUND(D12/J12,4),0) -> 0 | M12: =IFERROR(ROUND(E12/J12,4),0) -> 1 | N12: =IFERROR(ROUND(F12/J12,4),0) -> 0 | O12: =IFERROR(ROUND(G12/J12,4),0) -> 0 | P12: =IFERROR(ROUND(H12/J12,4),0) -> 0
A13: DPT_MWR | B13: Miscellaneous withdrawal | C13: =COUNTIFS(TestCase!$A:$A,$A13,TestCase!$G:$G,C$5) -> 0 | D13: =COUNTIFS(TestCase!$A:$A,$A13,TestCase!$G:$G,D$5) -> 0 | E13: =COUNTIFS(TestCase!$A:$A,$A13,TestCase!$G:$G,E$5) -> 29 | F13: =COUNTIFS(TestCase!$A:$A,$A13,TestCase!$G:$G,F$5) -> 0 | G13: =COUNTIFS(TestCase!$A:$A,$A13,TestCase!$G:$G,G$5) -> 0 | H13: =COUNTIFS(TestCase!$A:$A,$A13,TestCase!$G:$G,H$5) -> 0 | I13: =COUNTIFS(TestCase!$A:$A,$A13,TestCase!$G:$G,I$5) -> 0 | J13: =SUM(C13:H13) -> 29 | K13: =IFERROR(ROUND(C13/J13,4),0) -> 0 | L13: =IFERROR(ROUND(D13/J13,4),0) -> 0 | M13: =IFERROR(ROUND(E13/J13,4),0) -> 1 | N13: =IFERROR(ROUND(F13/J13,4),0) -> 0 | O13: =IFERROR(ROUND(G13/J13,4),0) -> 0 | P13: =IFERROR(ROUND(H13/J13,4),0) -> 0
A14: DPT_TRF | B14: Transfer from deposit account to deposit account | C14: =COUNTIFS(TestCase!$A:$A,$A14,TestCase!$G:$G,C$5) -> 0 | D14: =COUNTIFS(TestCase!$A:$A,$A14,TestCase!$G:$G,D$5) -> 0 | E14: =COUNTIFS(TestCase!$A:$A,$A14,TestCase!$G:$G,E$5) -> 43 | F14: =COUNTIFS(TestCase!$A:$A,$A14,TestCase!$G:$G,F$5) -> 0 | G14: =COUNTIFS(TestCase!$A:$A,$A14,TestCase!$G:$G,G$5) -> 0 | H14: =COUNTIFS(TestCase!$A:$A,$A14,TestCase!$G:$G,H$5) -> 0 | I14: =COUNTIFS(TestCase!$A:$A,$A14,TestCase!$G:$G,I$5) -> 0 | J14: =SUM(C14:H14) -> 43 | K14: =IFERROR(ROUND(C14/J14,4),0) -> 0 | L14: =IFERROR(ROUND(D14/J14,4),0) -> 0 | M14: =IFERROR(ROUND(E14/J14,4),0) -> 1 | N14: =IFERROR(ROUND(F14/J14,4),0) -> 0 | O14: =IFERROR(ROUND(G14/J14,4),0) -> 0 | P14: =IFERROR(ROUND(H14/J14,4),0) -> 0
A15: DPT_IFC | B15: Adjust deposit interest | C15: =COUNTIFS(TestCase!$A:$A,$A15,TestCase!$G:$G,C$5) -> 0 | D15: =COUNTIFS(TestCase!$A:$A,$A15,TestCase!$G:$G,D$5) -> 0 | E15: =COUNTIFS(TestCase!$A:$A,$A15,TestCase!$G:$G,E$5) -> 0 | F15: =COUNTIFS(TestCase!$A:$A,$A15,TestCase!$G:$G,F$5) -> 0 | G15: =COUNTIFS(TestCase!$A:$A,$A15,TestCase!$G:$G,G$5) -> 0 | H15: =COUNTIFS(TestCase!$A:$A,$A15,TestCase!$G:$G,H$5) -> 0 | I15: =COUNTIFS(TestCase!$A:$A,$A15,TestCase!$G:$G,I$5) -> 0 | J15: =SUM(C15:H15) -> 0 | K15: =IFERROR(ROUND(C15/J15,4),0) -> 0 | L15: =IFERROR(ROUND(D15/J15,4),0) -> 0 | M15: =IFERROR(ROUND(E15/J15,4),0) -> 0 | N15: =IFERROR(ROUND(F15/J15,4),0) -> 0 | O15: =IFERROR(ROUND(G15/J15,4),0) -> 0 | P15: =IFERROR(ROUND(H15/J15,4),0) -> 0
A16: DPT_CIP | B16: Interest payment by cash | C16: =COUNTIFS(TestCase!$A:$A,$A16,TestCase!$G:$G,C$5) -> 0 | D16: =COUNTIFS(TestCase!$A:$A,$A16,TestCase!$G:$G,D$5) -> 0 | E16: =COUNTIFS(TestCase!$A:$A,$A16,TestCase!$G:$G,E$5) -> 0 | F16: =COUNTIFS(TestCase!$A:$A,$A16,TestCase!$G:$G,F$5) -> 0 | G16: =COUNTIFS(TestCase!$A:$A,$A16,TestCase!$G:$G,G$5) -> 0 | H16: =COUNTIFS(TestCase!$A:$A,$A16,TestCase!$G:$G,H$5) -> 0 | I16: =COUNTIFS(TestCase!$A:$A,$A16,TestCase!$G:$G,I$5) -> 0 | J16: =SUM(C16:H16) -> 0 | K16: =IFERROR(ROUND(C16/J16,4),0) -> 0 | L16: =IFERROR(ROUND(D16/J16,4),0) -> 0 | M16: =IFERROR(ROUND(E16/J16,4),0) -> 0 | N16: =IFERROR(ROUND(F16/J16,4),0) -> 0 | O16: =IFERROR(ROUND(G16/J16,4),0) -> 0 | P16: =IFERROR(ROUND(H16/J16,4),0) -> 0
A17: DPT_DIP | B17: Interest payment to deposit account | C17: =COUNTIFS(TestCase!$A:$A,$A17,TestCase!$G:$G,C$5) -> 0 | D17: =COUNTIFS(TestCase!$A:$A,$A17,TestCase!$G:$G,D$5) -> 0 | E17: =COUNTIFS(TestCase!$A:$A,$A17,TestCase!$G:$G,E$5) -> 0 | F17: =COUNTIFS(TestCase!$A:$A,$A17,TestCase!$G:$G,F$5) -> 0 | G17: =COUNTIFS(TestCase!$A:$A,$A17,TestCase!$G:$G,G$5) -> 0 | H17: =COUNTIFS(TestCase!$A:$A,$A17,TestCase!$G:$G,H$5) -> 0 | I17: =COUNTIFS(TestCase!$A:$A,$A17,TestCase!$G:$G,I$5) -> 0 | J17: =SUM(C17:H17) -> 0 | K17: =IFERROR(ROUND(C17/J17,4),0) -> 0 | L17: =IFERROR(ROUND(D17/J17,4),0) -> 0 | M17: =IFERROR(ROUND(E17/J17,4),0) -> 0 | N17: =IFERROR(ROUND(F17/J17,4),0) -> 0 | O17: =IFERROR(ROUND(G17/J17,4),0) -> 0 | P17: =IFERROR(ROUND(H17/J17,4),0) -> 0
A18: DPT_MIP | B18: Miscellaneous interest payment | C18: =COUNTIFS(TestCase!$A:$A,$A18,TestCase!$G:$G,C$5) -> 0 | D18: =COUNTIFS(TestCase!$A:$A,$A18,TestCase!$G:$G,D$5) -> 0 | E18: =COUNTIFS(TestCase!$A:$A,$A18,TestCase!$G:$G,E$5) -> 0 | F18: =COUNTIFS(TestCase!$A:$A,$A18,TestCase!$G:$G,F$5) -> 0 | G18: =COUNTIFS(TestCase!$A:$A,$A18,TestCase!$G:$G,G$5) -> 0 | H18: =COUNTIFS(TestCase!$A:$A,$A18,TestCase!$G:$G,H$5) -> 0 | I18: =COUNTIFS(TestCase!$A:$A,$A18,TestCase!$G:$G,I$5) -> 0 | J18: =SUM(C18:H18) -> 0 | K18: =IFERROR(ROUND(C18/J18,4),0) -> 0 | L18: =IFERROR(ROUND(D18/J18,4),0) -> 0 | M18: =IFERROR(ROUND(E18/J18,4),0) -> 0 | N18: =IFERROR(ROUND(F18/J18,4),0) -> 0 | O18: =IFERROR(ROUND(G18/J18,4),0) -> 0 | P18: =IFERROR(ROUND(H18/J18,4),0) -> 0
... A32: DPT_HIS | B32: Transaction history inquiry | C32: =COUNTIFS(TestCase!$A:$A,$A32,TestCase!$G:$G,C$5) -> 0 | D32: =COUNTIFS(TestCase!$A:$A,$A32,TestCase!$G:$G,D$5) -> 0 | E32: =COUNTIFS(TestCase!$A:$A,$A32,TestCase!$G:$G,E$5) -> 0 | F32: =COUNTIFS(TestCase!$A:$A,$A32,TestCase!$G:$G,F$5) -> 0 | G32: =COUNTIFS(TestCase!$A:$A,$A32,TestCase!$G:$G,G$5) -> 0 | H32: =COUNTIFS(TestCase!$A:$A,$A32,TestCase!$G:$G,H$5) -> 0 | I32: =COUNTIFS(TestCase!$A:$A,$A32,TestCase!$G:$G,I$5) -> 0 | J32: =SUM(C32:H32) -> 0 | K32: =IFERROR(ROUND(C32/J32,4),0) -> 0 | L32: =IFERROR(ROUND(D32/J32,4),0) -> 0 | M32: =IFERROR(ROUND(E32/J32,4),0) -> 0 | N32: =IFERROR(ROUND(F32/J32,4),0) -> 0 | O32: =IFERROR(ROUND(G32/J32,4),0) -> 0 | P32: =IFERROR(ROUND(H32/J32,4),0) -> 0
A33: Total | C33: =SUM(C7:C32) -> 0 | D33: =SUM(D7:D32) -> 0 | E33: =SUM(E7:E32) -> 352 | F33: =SUM(F7:F32) -> 0 | G33: =SUM(G7:G32) -> 0 | H33: =SUM(H7:H32) -> 0 | I33: =SUM(I7:I32) -> 0 | J33: =SUM(J7:J32) -> 352 | K33: =IFERROR(100%-SUM(L33:P33),0) -> 0 | L33: =IFERROR(ROUND(D33/$J$33,4),0) -> 0 | M33: =IFERROR(ROUND(E33/$J$33,4),0) -> 1 | N33: =IFERROR(ROUND(F33/$J$33,4),0) -> 0 | O33: =IFERROR(ROUND(G33/$J$33,4),0) -> 0 | P33: =IFERROR(ROUND(H33/$J$33,4),0) -> 0
A35: Remark: Status of Test Scenario on section “Overall Status”:
A36: - Passed = Test Scenario has been tested as planned and application works as expected result.
A37: - Failed = Test Scenario has been tested as planned but application does not work as expected.
A38: - Blocked = Test Scenario could not be tested as planned because there is an outstanding defect in related function area.
A39: - Not Completed = Test Scenario has been tested as planned but not yet finished due to awaiting test result (ex: require EOD batch).
A40: - No Run (+) = Test Scenario has not been tested as planned.
A41: - Pending = Test Scenario will be tested after confirming about the business.
A42: - Cancel (-) = Test Scenario could not be tested because of wrong condition, not suitable with the environment.

Sheet TestCase
A2: TEST CASES
A3: Environment:
A5: Scenario ID | B5: Scenario name | C5: Test case ID | D5: Test condition ID | E5: Condition | F5: Expected Result | G5: Result | H5: Comments | I5: Create date | J5: 1st test | K5: 2nd test | L5: 3rd test | M5: Executor | N5: Creator (Editor) | O5: Update date
A6: ='Scenario Test'!$A$7 -> DPT_OPN | B6: =VLOOKUP(TestCase!A6,'Scenario Test'!$A$5:$B$129,2,0) -> Open new deposit account
A7: ='Scenario Test'!$A$7 -> DPT_OPN | B7: =VLOOKUP(TestCase!A7,'Scenario Test'!$A$5:$B$129,2,0) -> Open new deposit account | C7: OPN_001_001 | E7: Customer - Customer type: Single customer - Customer status: Normal Catalogue - Deposit type: Current - Catalogue status: Normal 1. Open "Open new deposit account" screen 2. Choose Customer type 3. Input Customer code 4. Input Catalogue code 5. Input Reason of Account Opening 6. Click Accpet | F7: -Transaction successfully - Check table data + o9deposit: DepositAccount, DepositAccountExtension, DepositAccountGLs, DepositAccountIFCGLs, IFCBalance, IFCBalanceDetail, DepositHistory, DepositStatement, AccountLinkage, Transaction, TransactionDetail + o9admin: TransactionJournalDone, Transaction, TransactionDetail | G7: + | I7: 45617 | N7: VyHNT
A8: ='Scenario Test'!$A$7 -> DPT_OPN | B8: =VLOOKUP(TestCase!A8,'Scenario Test'!$A$5:$B$129,2,0) -> Open new deposit account | C8: OPN_001_002 | E8: Customer - Customer type: Single customer - Customer status: Normal Catalogue - Deposit type: Saving - Catalogue status: Normal 1. Open "Open new deposit account" screen 2. Choose Customer type 3. Input Customer code 4. Input Catalogue code 5. Input Reason of Account Opening 6. Click Accpet | F8: - Check table data + o9deposit: DepositAccount, DepositAccountExtension, DepositAccountGLs, DepositAccountIFCGLs, IFCBalance, DepositHistory, DepositStatement, AccountLinkage, Transaction, TransactionDetail + o9admin: TransactionJournalDone, Transaction, TransactionDetail | G8: + | I8: 45617 | N8: VyHNT
A9: ='Scenario Test'!$A$7 -> DPT_OPN | B9: =VLOOKUP(TestCase!A9,'Scenario Test'!$A$5:$B$129,2,0) -> Open new deposit account | C9: OPN_001_003 | E9: Customer - Customer type: Single customer - Customer status: Normal Catalogue - Deposit type: Fixed deposit - Deposit sub type <> Prepaid fixed deposit - Catalogue status: Normal To account number - Deposit type: Current/ Saving - Deposit sub type <> Shwe Cash call - Same customer type with deposit will open - Same customer code with deposit will open 1. Open "Open new deposit account" screen 2. Choose Customer type 3. Input Customer code 4. Input Catalogue code 5. Input To account number 6. Input Reason of Account Opening 7. Click Accpet | F9: -Transaction successfully - Check table data + o9deposit: DepositAccount, DepositAccountExtension, DepositAccountGLs, DepositAccountIFCGLs, IFCBalance, DepositHistory, DepositStatement, AccountLinkage, Transaction, TransactionDetail + o9admin: TransactionJournalDone, Transaction, TransactionDetail | G9: + | I9: 45617 | N9: VyHNT
A10: ='Scenario Test'!$A$7 -> DPT_OPN | B10: =VLOOKUP(TestCase!A10,'Scenario Test'!$A$5:$B$129,2,0) -> Open new deposit account | C10: OPN_001_004 | E10: Customer - Customer type: Single customer - Customer status: Normal Catalogue - Deposit type: Fixed deposit - Deposit sub type: Prepaid fixed deposit - Catalogue status: Normal To account number - Deposit type: Current/ Saving - Deposit sub type <> Shwe Cash call - Same customer type with deposit will open - Same customer code with deposit will open 1. Open "Open new deposit account" screen 2. Choose Customer type 3. Input Customer code 4. Input Catalogue code 5. Input To account number 6. Input Reason of Account Opening 7. Click Accpet | F10: -Transaction successfully - Check table data + o9deposit: DepositAccount, DepositAccountExtension, DepositAccountGLs, DepositAccountIFCGLs, IFCBalance, IFCBalanceDetail, DepositHistory, DepositStatement, AccountLinkage, Transaction, TransactionDetail + o9admin: TransactionJournalDone, Transaction, TransactionDetail | G10: + | I10: 45617 | N10: VyHNT
A11: ='Scenario Test'!$A$7 -> DPT_OPN | B11: =VLOOKUP(TestCase!A11,'Scenario Test'!$A$5:$B$129,2,0) -> Open new deposit account | C11: OPN_001_005 | E11: Customer - Customer type: Single customer - Customer status: Normal Catalogue - Deposit type: Current (currency is not MMK) - Catalogue status: Normal - Catalogue code: CAUSD0000/ CASGD0000/ CAEUR0000 1. Open "Open new deposit account" screen 2. Choose Customer type 3. Input Customer code 4. Input Catalogue code 5. Input Reason of Account Opening 6. Click Accpet | F11: -Transaction successfully - Check table data + o9deposit: DepositAccount, DepositAccountExtension, DepositAccountGLs, DepositAccountIFCGLs, IFCBalance, IFCBalanceDetail, DepositHistory, DepositStatement, AccountLinkage, Transaction, TransactionDetail + o9admin: TransactionJournalDone, Transaction, TransactionDetail | G11: + | I11: 45617 | N11: VyHNT
A12: ='Scenario Test'!$A$7 -> DPT_OPN | B12: =VLOOKUP(TestCase!A12,'Scenario Test'!$A$5:$B$129,2,0) -> Open new deposit account | C12: OPN_001_006 | E12: Customer - Customer type: Customer linkage - Customer status: Normal - Relation customer is empty Catalogue - Deposit type: Current (currency is not MMK) - Catalogue status: Normal - Catalogue code: CAUSD0000/ CASGD0000/ CAEUR0000 1. Open "Open new deposit account" screen 2. Choose Customer type 3. Input Customer code 4. Input Catalogue code 5. Input Reason of Account Opening 6. Click Accpet | F12: -Transaction successfully - Check table data + o9deposit: DepositAccount, DepositAccountExtension, DepositAccountGLs, DepositAccountIFCGLs, IFCBalance, DepositHistory, DepositStatement, AccountLinkage, Transaction, TransactionDetail + o9admin: TransactionJournalDone, Transaction, TransactionDetail | G12: + | I12: 45617 | N12: VyHNT
A13: ='Scenario Test'!$A$7 -> DPT_OPN | B13: =VLOOKUP(TestCase!A13,'Scenario Test'!$A$5:$B$129,2,0) -> Open new deposit account | C13: OPN_001_007 | E13: Customer - Customer type: Customer group - Customer status: Normal - Relation customer is empty Catalogue - Deposit type: Current (currency is not MMK) - Catalogue status: Normal - Catalogue code: CAUSD0001/ CASGD0001/ CAEUR0001 1. Open "Open new deposit account" screen 2. Choose Customer type 3. Input Customer code 4. Input Catalogue code 5. Input Reason of Account Opening 6. Click Accpet | F13: -Transaction successfully - Check table data + o9deposit: DepositAccount, DepositAccountExtension, DepositAccountGLs, DepositAccountIFCGLs, IFCBalance, DepositHistory, DepositStatement, AccountLinkage, Transaction, TransactionDetail + o9admin: TransactionJournalDone, Transaction, TransactionDetail | G13: + | I13: 45617 | N13: VyHNT
A14: ='Scenario Test'!$A$7 -> DPT_OPN | B14: =VLOOKUP(TestCase!A14,'Scenario Test'!$A$5:$B$129,2,0) -> Open new deposit account | C14: OPN_001_008 | E14: Customer - Customer type: Customer linkage - Customer status: Normal - Relation customer is not empty Catalogue - Deposit type: Current (currency is not MMK) - Catalogue status: Normal - Catalogue code: CAUSD0000/ CASGD0000/ CAEUR0000 1. Open "Open new deposit account" screen 2. Choose Customer type 3. Input Customer code 4. Input Catalogue code 5. Input Reason of Account Opening 6. Click Accpet | F14: -Transaction successfully - Check table data + o9deposit: DepositAccount, DepositAccountExtension, DepositAccountGLs, DepositAccountIFCGLs, IFCBalance, DepositHistory, DepositStatement, AccountLinkage, Transaction, TransactionDetail + o9admin: TransactionJournalDone, Transaction, TransactionDetail | G14: + | I14: 45617 | N14: VyHNT
A15: ='Scenario Test'!$A$7 -> DPT_OPN | B15: =VLOOKUP(TestCase!A15,'Scenario Test'!$A$5:$B$129,2,0) -> Open new deposit account | C15: OPN_001_009 | E15: Customer - Customer type: Customer group - Customer status: Normal - Relation customer is not empty Catalogue - Deposit type: Current (currency is not MMK) - Catalogue status: Normal - Catalogue code: CAUSD0001/ CASGD0001/ CAEUR0001 1. Open "Open new deposit account" screen 2. Choose Customer type 3. Input Customer code 4. Input Catalogue code 5. Input Reason of Account Opening 6. Click Accpet | F15: -Transaction successfully - Check table data + o9deposit: DepositAccount, DepositAccountExtension, DepositAccountGLs, DepositAccountIFCGLs, IFCBalance, DepositHistory, DepositStatement, AccountLinkage, Transaction, TransactionDetail + o9admin: TransactionJournalDone, Transaction, TransactionDetail | G15: + | I15: 45617 | N15: VyHNT
A16: ='Scenario Test'!$A$7 -> DPT_OPN | B16: =VLOOKUP(TestCase!A16,'Scenario Test'!$A$5:$B$129,2,0) -> Open new deposit account | C16: OPN_001_010 | E16: Customer - Customer type: Customer linkage - Customer status: Normal - Relation customers is empty Catalogue - Deposit type: Saving - Catalogue status: Normal 1. Open "Open new deposit account" screen 2. Choose Customer type 3. Input Customer code 4. Input Catalogue code 5. Input Reason of Account Opening 6. Click Accpet | F16: -Transaction successfully - Check table data + o9deposit: DepositAccount, DepositAccountExtension, DepositAccountGLs, DepositAccountIFCGLs, IFCBalance, IFCBalanceDetail, DepositHistory, DepositStatement, AccountLinkage, Transaction, TransactionDetail + o9admin: TransactionJournalDone, Transaction, TransactionDetail | G16: + | I16: 45617 | N16: VyHNT
A17: ='Scenario Test'!$A$7 -> DPT_OPN | B17: =VLOOKUP(TestCase!A17,'Scenario Test'!$A$5:$B$129,2,0) -> Open new deposit account | C17: OPN_001_011 | E17: Customer - Customer type: Customer group - Customer status: Normal - Relation customers is empty Catalogue - Deposit type: Saving - Catalogue status: Normal 1. Open "Open new deposit account" screen 2. Choose Customer type 3. Input Customer code 4. Input Catalogue code 5. Input Reason of Account Opening 6. Click Accpet | F17: - Check table data + o9deposit: DepositAccount, DepositAccountExtension, DepositAccountGLs, DepositAccountIFCGLs, IFCBalance, DepositHistory, DepositStatement, AccountLinkage, Transaction, TransactionDetail + o9admin: TransactionJournalDone, Transaction, TransactionDetail | G17: + | I17: 45617 | N17: VyHNT
A18: ='Scenario Test'!$A$7 -> DPT_OPN | B18: =VLOOKUP(TestCase!A18,'Scenario Test'!$A$5:$B$129,2,0) -> Open new deposit account | C18: OPN_001_012 | E18: Customer - Customer type: Customer linkage - Customer status: Normal - Relation customers is not empty Catalogue - Deposit type: Saving - Catalogue status: Normal 1. Open "Open new deposit account" screen 2. Choose Customer type 3. Input Customer code 4. Input Catalogue code 5. Input Reason of Account Opening 6. Click Accpet | F18: - Check table data + o9deposit: DepositAccount, DepositAccountExtension, DepositAccountGLs, DepositAccountIFCGLs, IFCBalance, DepositHistory, DepositStatement, AccountLinkage, Transaction, TransactionDetail + o9admin: TransactionJournalDone, Transaction, TransactionDetail | G18: + | I18: 45617 | N18: VyHNT
... A21: ='Scenario Test'!$A$7 -> DPT_OPN | B21: =VLOOKUP(TestCase!A21,'Scenario Test'!$A$5:$B$129,2,0) -> Open new deposit account | C21: OPN_001_015 | E21: Catalogue code is empty | F21: Transaction fail | G21: + | I21: 45617 | N21: VyHNT
A22: ='Scenario Test'!$A$7 -> DPT_OPN | B22: =VLOOKUP(TestCase!A22,'Scenario Test'!$A$5:$B$129,2,0) -> Open new deposit account | C22: OPN_001_016 | E22: Reason of account opening is empty | F22: Transaction fail | G22: + | H22: test manual | I22: 45617 | N22: VyHNT
A23: ='Scenario Test'!$A$7 -> DPT_OPN | B23: =VLOOKUP(TestCase!A23,'Scenario Test'!$A$5:$B$129,2,0) -> Open new deposit account | C23: OPN_001_017 | E23: Customer status <> Normal | F23: Transaction fail | G23: + | I23: 45617 | N23: VyHNT
A24: ='Scenario Test'!$A$7 -> DPT_OPN | B24: =VLOOKUP(TestCase!A24,'Scenario Test'!$A$5:$B$129,2,0) -> Open new deposit account | C24: OPN_001_018 | E24: Catalogue status <> Normal | F24: Transaction fail | G24: + | I24: 45617 | N24: VyHNT
A25: ='Scenario Test'!$A$7 -> DPT_OPN | B25: =VLOOKUP(TestCase!A25,'Scenario Test'!$A$5:$B$129,2,0) -> Open new deposit account | C25: OPN_001_019 | E25: Customer - Customer type: Single customer - Customer status: Normal Catalogue - Deposit type: Current (currency is not MMK) - Catalogue status: Normal - Catalogue code: CAUSD0001/ CASGD0001/ CAEUR0001 | F25: Transaction fail | G25: + | I25: 45617 | N25: VyHNT
A26: ='Scenario Test'!$A$7 -> DPT_OPN | B26: =VLOOKUP(TestCase!A26,'Scenario Test'!$A$5:$B$129,2,0) -> Open new deposit account | C26: OPN_001_020 | E26: Customer - Customer type: Customer linkage - Customer status: Normal - Relation customer is empty Catalogue - Deposit type: Current (currency is not MMK) - Catalogue status: Normal - Catalogue code: CAUSD0001/ CASGD0001/ CAEUR0001 | F26: Transaction fail | G26: + | I26: 45617 | N26: VyHNT
A27: ='Scenario Test'!$A$7 -> DPT_OPN | B27: =VLOOKUP(TestCase!A27,'Scenario Test'!$A$5:$B$129,2,0) -> Open new deposit account | C27: OPN_001_021 | E27: Customer - Customer type: Customer group - Customer status: Normal - Relation customer is empty Catalogue - Deposit type: Current (currency is not MMK) - Catalogue status: Normal - Catalogue code: CAUSD0000/ CASGD0000/ CAEUR0000 | F27: Transaction fail | G27: + | I27: 45617 | N27: VyHNT
A28: ='Scenario Test'!$A$7 -> DPT_OPN | B28: =VLOOKUP(TestCase!A28,'Scenario Test'!$A$5:$B$129,2,0) -> Open new deposit account | C28: OPN_001_022 | E28: Catalogue - Deposit type: Fixed deposit - Deposit sub type: Prepaid fixed deposit - Catalogue status: Normal To account number - Deposit type is Fixed deposit - Same customer type with deposit will open - Same customer code with deposit will open | F28: Transaction fail | G28: + | I28: 45617 | N28: VyHNT
A29: ='Scenario Test'!$A$7 -> DPT_OPN | B29: =VLOOKUP(TestCase!A29,'Scenario Test'!$A$5:$B$129,2,0) -> Open new deposit account | C29: OPN_001_023 | E29: Catalogue - Deposit type: Fixed deposit - Deposit sub type: Prepaid fixed deposit - Catalogue status: Normal To account number - Deposit type: Current/ Saving - Deposit sub type: Shwe Cash call - Same customer type with deposit will open - Same customer code with deposit will open | F29: Transaction fail | G29: + | I29: 45617 | N29: VyHNT
A30: ='Scenario Test'!$A$7 -> DPT_OPN | B30: =VLOOKUP(TestCase!A30,'Scenario Test'!$A$5:$B$129,2,0) -> Open new deposit account | C30: OPN_001_024 | E30: Catalogue - Deposit type: Fixed deposit - Deposit sub type: Prepaid fixed deposit - Catalogue status: Normal To account number - Deposit type: Current/ Saving - Deposit sub type <> Shwe Cash call - Customer type different with deposit will open - Same customer code with deposit will open | F30: Transaction fail | G30: + | I30: 45617 | N30: VyHNT
A31: ='Scenario Test'!$A$7 -> DPT_OPN | B31: =VLOOKUP(TestCase!A31,'Scenario Test'!$A$5:$B$129,2,0) -> Open new deposit account | C31: OPN_001_025 | E31: Catalogue - Deposit sub type: Prepaid fixed deposit - Catalogue status: Normal To account number - Deposit type: Current/ Saving - Deposit sub type <> Shwe Cash call - Same customer type with deposit will open - Customer code different with deposit will open | F31: Transaction fail | G31: + | I31: 45617 | N31: VyHNT
A32: ='Scenario Test'!$A$7 -> DPT_OPN | B32: =VLOOKUP(TestCase!A32,'Scenario Test'!$A$5:$B$129,2,0) -> Open new deposit account | C32: OPN_001_026 | E32: Reverse transaction | F32: -Transaction successfully - Check table data + o9deposit: DepositAccount, DepositAccountExtension, DepositAccountGLs, DepositAccountIFCGLs, IFCBalance, IFCBalanceDetail, DepositHistory, DepositStatement, AccountLinkage, Transaction, TransactionDetail + o9admin: TransactionJournalDone, Transaction, TransactionDetail | G32: + | H32: test manual | I32: 45617 | N32: VyHNT
A33: ='Scenario Test'!$A$8 -> DPT_APR | B33: =VLOOKUP(TestCase!A33,'Scenario Test'!$A$5:$B$129,2,0) -> Approve deposit account
A34: ='Scenario Test'!$A$8 -> DPT_APR | B34: =VLOOKUP(TestCase!A34,'Scenario Test'!$A$5:$B$129,2,0) -> Approve deposit account | C34: APR_001_001 | E34: - Deposit status: Pending to approve - Branch account same branch with teller 1. Open "Approve deposit account" screen 2. Input Account number 3. Click Accept | F34: -Transaction successfully - Check table data + o9deposit: DepositAccount, DepositHistory, DepositStatement, Transaction, TransactionDetail + o9admin: TransactionJournalDone, Transaction, TransactionDetail | G34: + | I34: 45617 | N34: VyHNT
A35: ='Scenario Test'!$A$8 -> DPT_APR | B35: =VLOOKUP(TestCase!A35,'Scenario Test'!$A$5:$B$129,2,0) -> Approve deposit account | C35: APR_001_002 | E35: - Deposit status <> Pending to approve - Branch account same branch with teller | F35: Transaction fail | G35: + | I35: 45617 | N35: VyHNT
A36: ='Scenario Test'!$A$8 -> DPT_APR | B36: =VLOOKUP(TestCase!A36,'Scenario Test'!$A$5:$B$129,2,0) -> Approve deposit account | C36: APR_001_003 | E36: - Deposit status: Pending to approve - Branch account different with branch with teller | F36: Transaction fail | G36: + | I36: 45617 | N36: VyHNT
A37: ='Scenario Test'!$A$8 -> DPT_APR | B37: =VLOOKUP(TestCase!A37,'Scenario Test'!$A$5:$B$129,2,0) -> Approve deposit account | C37: APR_001_004 | E37: Account number does not exist | F37: Transaction fail | G37: + | I37: 45617 | N37: VyHNT
A38: ='Scenario Test'!$A$8 -> DPT_APR | B38: =VLOOKUP(TestCase!A38,'Scenario Test'!$A$5:$B$129,2,0) -> Approve deposit account | C38: APR_001_005 | E38: Reverse transaction | F38: -Transaction successfully - Check table data + o9deposit: DepositAccount, DepositHistory, DepositStatement, Transaction, TransactionDetail + o9admin: TransactionJournalDone, Transaction, TransactionDetail | G38: + | H38: test manual | I38: 45617 | N38: VyHNT
A39: ='Scenario Test'!$A$9 -> DPT_REJ | B39: =VLOOKUP(TestCase!A39,'Scenario Test'!$A$5:$B$129,2,0) -> Reject deposit account
A40: ='Scenario Test'!$A$9 -> DPT_REJ | B40: =VLOOKUP(TestCase!A40,'Scenario Test'!$A$5:$B$129,2,0) -> Reject deposit account | C40: REJ_001_001 | E40: Deposit status: Pending to approve 1. Open "Reject deposit account" screen 2. Input Account number 3. Click Accept | F40: -Transaction successfully - Check table data + o9deposit: DepositAccount, DepositHistory, DepositStatement, Transaction, TransactionDetail + o9admin: TransactionJournalDone, Transaction, TransactionDetail | G40: + | I40: 45617 | N40: VyHNT
A41: ='Scenario Test'!$A$9 -> DPT_REJ | B41: =VLOOKUP(TestCase!A41,'Scenario Test'!$A$5:$B$129,2,0) -> Reject deposit account | C41: REJ_001_002 | E41: Deposit status <> Pending to approve | F41: Transaction fail | G41: + | I41: 45617 | N41: VyHNT
A42: ='Scenario Test'!$A$9 -> DPT_REJ | B42: =VLOOKUP(TestCase!A42,'Scenario Test'!$A$5:$B$129,2,0) -> Reject deposit account | C42: REJ_001_003 | E42: Account number does not exist | F42: Transaction fail | G42: + | I42: 45617 | N42: VyHNT
A43: ='Scenario Test'!$A$9 -> DPT_REJ | B43: =VLOOKUP(TestCase!A43,'Scenario Test'!$A$5:$B$129,2,0) -> Reject deposit account | C43: REJ_001_004 | E43: Reverse transaction | F43: -Transaction successfully - Check table data + o9deposit: DepositAccount, DepositHistory, DepositStatement, Transaction, TransactionDetail + o9admin: TransactionJournalDone, Transaction, TransactionDetail | G43: + | I43: 45617 | N43: VyHNT
A44: ='Scenario Test'!$A$10 -> DPT_CDP | B44: =VLOOKUP(TestCase!A44,'Scenario Test'!$A$5:$B$129,2,0) -> Cash deposit
...

Sheet UpdateData
A1: Action | B1: Update data | C1: Update related table
C2: o9accounting | E2: o9admin | G2: o9cash | I2: o9deposit
C3: Table name | D3: Action | E3: Table name | F3: Action | G3: Table name | H3: Action | I3: Table name | J3: Action
A4: Deposit money for deposit account (current, saving, fixed deposit) | B4: Deposit account - Status: Normal (if prevoius status is New/ Dormant) - Increase Current balance, Available balance - Increase Deposit Amount, Week Credit, Month Credit, Quarter Credit, Semi - Annual Credit and Year Credit - BeginOfTenor = Working, EndOfTenor = Working date + tenor - LastChangeDormantToNormalDate (if previous status is Dormant) Deposit by cash - Increase Customer deposit, Total In, Closing balance of Cash flow Deposit by deposit - Decrease Current balance, Available balance - Increase Withdraw Amount, Week Debit, Month Debit, Quarter Debit, Semi - Annual Debit and Year Debit Deposit by GL - Decrease GL Balance | C4: GLEntries | D4: Insert new row | E4: TransactionJournalDone | F4: Insert new row | G4: CashList | H4: - CurrencyCode already existed: Update old row (update CurrentBalance) - CurrencyCode does not exist: Insert new row | I4: DepositAccount | J4: Update old row - DepositStatus (if prevoius status is New/ Dormant) - Psts - CurrentBalance, DepositAmount, WeekCredit, MonthCredit, QuarterCredit, SemiAnnualCredit, YearCredit - LastTransactionDate, UpdatedOnUtc - BeginOfTenor, EndOfTenor (if deposit type is Fixed Deposit) - LastChangeDormantToNormalDate (if previous status is Dormant) Update old row (if deposit by deposit) - Psts - CurrentBalance, WithdrawAmount, WeekDebit, MonthDebit, QuarterDebit, SemiAnnualDebit, YearDebit - LastTransactionDate, UpdatedOnUtc
C5: AccountBalance | D5: Update old row (update Balance) | E5: ApproveTransactionHistory | F5: Insert new row | G5: CashStatement | H5: - CashierCode, CurrencyCode, CashType and ValueDate already existed: Update old row (update CashAmount) - CashierCode, CurrencyCode, CashType and ValueDate do not exist: Insert new row | I5: DepositStatement | J5: Insert new row
C6: AccountStatement | D6: Insert new row | E6: Transaction | F6: Insert new row | G6: CashTransaction | H6: Insert new row | I6: DepositHistory | J6: Insert new row
C7: Transaction | D7: Insert new row | E7: TransactionDetail | F7: Insert new row | G7: GLEntries | H7: Insert new row | I7: DepositAccountTrans | J7: Insert new row
C8: TransactionDetail | D8: Insert new row | G8: Transaction | H8: Insert new row | I8: GLEntries | J8: Insert new row
G9: TransactionDetail | H9: Insert new row | I9: Transaction | J9: Insert new row
I10: TransactionDetail | J10: Insert new row
A11: Withdraw money for deposit account (current, saving) | B11: Deposit account - Decrease Current balance, Available balance - Increase Withdraw Amount, Week Debit, Month Debit, Quarter Debit, Semi - Annual Debit and Year Debit Withdraw by cash - Increase Customer withdrawal, Total Out, decrease Closing balance of Cash flow Withdraw by deposit - Increase Current balance, Available balance - Increase Deposit Amount, Week Credit, Month Credit, Quarter Credit, Semi - Annual Credit and Year Credit Withdraw by GL - Increase GL Balance | C11: GLEntries | D11: Insert new row | E11: TransactionJournalDone | F11: Insert new row | G11: CashList | H11: Update old row (update CurrentBalance) | I11: DepositAccount | J11: Update old row - DepositStatus (if prevoius status is New) - Psts - CurrentBalance, WithdrawAmount, WeekDebit, MonthDebit, QuarterDebit, SemiAnnualDebit, YearDebit - LastTransactionDate, UpdatedOnUtc - LastChangeDormantToNormalDate (if previous status is Dormant) Update old row (if withdraw by deposit) - DepositStatus (if prevoius status is New) - Psts - CurrentBalance, DepositAmount, WeekCredit, MonthCredit, QuarterCredit, SemiAnnualCredit, YearCredit - LastTransactionDate, UpdatedOnUtc
C12: AccountBalance | D12: Update old row (update Balance) | E12: Transaction | F12: Insert new row | G12: CashStatement | H12: - CashierCode, CurrencyCode, CashType and ValueDate already existed: Update old row (update CashAmount) - CashierCode, CurrencyCode, CashType and ValueDate do not exist: Insert new row | I12: DepositStatement | J12: Insert new row
C13: AccountStatement | D13: Insert new row | E13: TransactionDetail | F13: Insert new row | G13: CashTransaction | H13: Insert new row | I13: DepositHistory | J13: Insert new row
C14: Transaction | D14: Insert new row | G14: GLEntries | H14: Insert new row | I14: DepositAccountTrans | J14: Insert new row
C15: TransactionDetail | D15: Insert new row | G15: Transaction | H15: Insert new row | I15: GLEntries | J15: Insert new row
G16: TransactionDetail | H16: Insert new row | I16: Transaction | J16: Insert new row
I17: TransactionDetail | J17: Insert new row
A18: Deposit money for prepaid fixed deposit | B18: Fixed deposit account - Status: Normal (if prevoius status is New) - Increase Current balance, Available balance - Increase Deposit Amount, Week Credit, Month Credit, Quarter Credit, Semi - Annual Credit and Year Credit - BeginOfTenor = Working, EndOfTenor = Working date + tenor - Increase Interest prepaid Linkage account - Increase Current balance, Available balance - Increase Deposit Amount, Week Credit, Month Credit, Quarter Credit, Semi - Annual Credit and Year Credit Deposit by cash - Increase Customer deposit, Total In, Closing balance of Cash flow Deposit by deposit - Decrease Current balance, Available balance - Increase Withdraw Amount, Week Debit, Month Debit, Quarter Debit, Semi - Annual Debit and Year Debit | C18: GLEntries | D18: Insert new row | E18: TransactionJournalDone | F18: Insert new row | G18: CashList | H18: - CurrencyCode already existed: Update old row (update CurrentBalance) - CurrencyCode does not exist: Insert new row | I18: DepositAccount | J18: Update old row (Prepaid fixed deposit) - DepositStatus (if prevoius status is New) - Psts - CurrentBalance, DepositAmount, WeekCredit, MonthCredit, QuarterCredit, SemiAnnualCredit, YearCredit - LastTransactionDate, UpdatedOnUtc - BeginOfTenor, EndOfTenor (if deposit type is Fixed Deposit) - LastChangeDormantToNormalDate (if previous status is Dormant) Update old row (linkage account) - Psts - CurrentBalance, DepositAmount, WeekCredit, MonthCredit, QuarterCredit, SemiAnnualCredit, YearCredit - LastTransactionDate, UpdatedOnUtc Update old row (if deposit by deposit) - Psts - CurrentBalance, WithdrawAmount, WeekDebit, MonthDebit, QuarterDebit, SemiAnnualDebit, YearDebit - LastTransactionDate, UpdatedOnUtc
C19: AccountBalance | D19: Update old row (update Balance) | E19: Transaction | F19: Insert new row | G19: CashStatement | H19: Insert new row | I19: IFCBalance | J19: Update old row (update PrepaidAmount)
C20: AccountStatement | D20: Insert new row | E20: TransactionDetail | F20: Insert new row | G20: CashTransaction | H20: Insert new row | I20: IFCBalanceDetail | J20: Insert new row
C21: Transaction | D21: Insert new row | G21: GLEntries | H21: Insert new row | I21: DepositStatement | J21: Insert new row
C22: TransactionDetail | D22: Insert new row | G22: Transaction | H22: Insert new row | I22: DepositHistory | J22: Insert new row
G23: TransactionDetail | H23: Insert new row | I23: DepositAccountTrans | J23: Insert new row
I24: DepositIFCBalanceTrans | J24: Insert new row
I25: GLEntries | J25: Insert new row
I26: Transaction | J26: Insert new row
I27: TransactionDetail | J27: Insert new row
A28: Close deposit account (current, saving, fixed deposit, prepaid fixed deposit) | B28: Deposit account - Status: Close - Close date = Working date - Current balance = Available balance = 0 - Increase Withdraw Amount, Week Debit, Month Debit, Quarter Debit, Semi - Annual Debit and Year Debit - Interest accrual = Intpbl = Interest due = 0 (If previous interest > 0) - Interest paid (new) = Interest paid (old) + Gross paid - IFC list: + Outstanding = 0 + Paid (new) = Paid (old) + Gross paid Close by cash - Increase Customer withdrawal, Total Out, decrease Closing balance of Cash flow Close by deposit - Increase Current balance, Available balance - Increase Deposit Amount, Week Credit, Month Credit, Quarter Credit, Semi - Annual Credit and Year Credit Close by GL - Increase GL Balance | C28: GLEntries | D28: Insert new row | E28: TransactionJournalDone | F28: Insert new row | G28: CashList | H28: - CurrencyCode already existed: Update old row (update CurrentBalance) - CurrencyCode does not exist: Insert new row | I28: DepositAccount | J28: Update old row - DepositStatus, Psts - CurrentBalance, WithdrawAmount, WeekDebit, MonthDebit, QuarterDebit, SemiAnnualDebit, YearDebit - LastTransactionDate, UpdatedOnUtc - InterestAccrual, Intpbl, IntersetDue, InterestPaid Update old row (if close by deposit) - DepositStatus (if prevoius status is New) - Psts - CurrentBalance, DepositAmount, WeekCredit, MonthCredit, QuarterCredit, SemiAnnualCredit, YearCredit - LastTransactionDate, UpdatedOnUtc
C29: AccountBalance | D29: Update old row (update Balance) | E29: Transaction | F29: Insert new row | G29: CashStatement | H29: - CashierCode, CurrencyCode, CashType and ValueDate already existed: Update old row (update CashAmount) - CashierCode, CurrencyCode, CashType and ValueDate do not exist: Insert new row | I29: IFCBalance | J29: Update old row (update Outstanding, Paid)
C30: AccountStatement | D30: Insert new row | E30: TransactionDetail | F30: Insert new row | G30: CashTransaction | H30: Insert new row | I30: IFCBalanceDetail | J30: Insert new row
C31: Transaction | D31: Insert new row | G31: GLEntries | H31: Insert new row | I31: DepositStatement | J31: Insert new row
C32: TransactionDetail | D32: Insert new row | G32: Transaction | H32: Insert new row | I32: DepositHistory | J32: Insert new row
G33: TransactionDetail | H33: Insert new row | I33: DepositAccountTrans | J33: Insert new row
I34: DepositIFCBalanceTrans | J34: Insert new row
I35: GLEntries | J35: Insert new row
I36: Transaction | J36: Insert new row
I37: TransactionDetail | J37: Insert new row
A38: Close early termination (fixed deposit) | B38: Deposit account - Status: Close - Close date = Working date - Current balance = Available balance = 0 - Increase Withdraw Amount, Week Debit, Month Debit, Quarter Debit, Semi - Annual Debit and Year Debit - Interest accrual = Intpbl = Interest due = 0 - Interest paid (new) = Interest paid (old) + Gross paid - IFC list: + IFC normal interest: Outstanding = 0 + IFC early interest: Paid = Gross paid Close by cash - Increase Customer withdrawal, Total Out, decrease Closing balance of Cash flow Close by deposit - Increase Current balance, Available balance - Increase Deposit Amount, Week Credit, Month Credit, Quarter Credit, Semi - Annual Credit and Year Credit Close by GL - Increase GL Balance | C38: GLEntries | D38: Insert new row | E38: TransactionJournalDone | F38: Insert new row | G38: CashList | H38: - CurrencyCode already existed: Update old row (update CurrentBalance) - CurrencyCode does not exist: Insert new row | I38: DepositAccount | J38: Update old row - DepositStatus, Psts - CurrentBalance, WithdrawAmount, WeekDebit, MonthDebit, QuarterDebit, SemiAnnualDebit, YearDebit - LastTransactionDate, UpdatedOnUtc - InterestAccrual, Intpbl, IntersetDue, InterestPaid Update old row (if close by deposit) - DepositStatus (if prevoius status is New) - Psts - CurrentBalance, DepositAmount, WeekCredit, MonthCredit, QuarterCredit, SemiAnnualCredit, YearCredit - LastTransactionDate, UpdatedOnUtc
C39: AccountBalance | D39: Update old row (update Balance) | E39: Transaction | F39: Insert new row | G39: CashStatement | H39: - CashierCode, CurrencyCode, CashType and ValueDate already existed: Update old row (update CashAmount) - CashierCode, CurrencyCode, CashType and ValueDate do not exist: Insert new row | I39: IFCBalance | J39: Update old row - IFC normal interest: Outstanding - IFC early interest: Paid
C40: AccountStatement | D40: Insert new row | E40: TransactionDetail | F40: Insert new row | G40: CashTransaction | H40: Insert new row | I40: IFCBalanceDetail | J40: Insert new row
...
